<?xml version="1.0" encoding="utf-8"?>
<!-- =================================================================================== -->
<!-- |    This document was autogenerated by xacro from kubo.urdf.xacro                | -->
<!-- |    EDITING THIS FILE BY HAND IS NOT RECOMMENDED                                 | -->
<!-- =================================================================================== -->
<!-- TODO: double check parameters. If correct, then shape meshes to look better -->
<!-- TODO: add meshes for sensors -->
<!-- TODO: add box blade -->
<robot name="kubo">
  <gazebo>
    <plugin filename="libgazebo_ros_control.so" name="gazebo_ros_control">
      <robotNamespace></robotNamespace>
      <robotParam>/robot_description</robotParam>
      <controlPeriod>0.001</controlPeriod>
      <legacyModeNS>true</legacyModeNS>
      <robotSimType>gazebo_ros_control/DefaultRobotHWSim</robotSimType>
    </plugin>
  </gazebo>
  <!-- steering drive controller -->
    <gazebo>
    <plugin filename="libgazebo_ros_diff_drive.so" name="differential_drive_controller_front">
      <rosDebugLevel>Debug</rosDebugLevel>
      <publishWheelTF>True</publishWheelTF>
      <publishTf>1</publishTf>
      <publishWheelJointState>true</publishWheelJointState>
      <alwaysOn>true</alwaysOn>/odometry/gps
      <updateRate>100.0</updateRate>
      <leftJoint>left_rear_axle</leftJoint>
      <rightJoint>right_rear_axle</rightJoint>
      <wheelSeparation>0.8</wheelSeparation>  
      <wheelDiameter>0.7</wheelDiameter>       
      <broadcastTF>1</broadcastTF>
      <wheelTorque>30</wheelTorque>
      <wheelAcceleration>1.8</wheelAcceleration>
      <commandTopic>cmd_vel</commandTopic>
      <odometryFrame>odom</odometryFrame>
      <odometryTopic>odom</odometryTopic>
      <robotBaseFrame>base_link</robotBaseFrame>
    </plugin>
  </gazebo>


  <gazebo reference="left_front_wheel">
  	<mu1 value="1.0"/>
  	<mu2 value="1.0"/>
  	<kp value="1000000.0" />
  	<kd value="1.0" />
  	<!--<fdir1 value="1 0 0"/> -->
  	<turnGravityOff>false</turnGravityOff>
  </gazebo>
  <gazebo reference="right_front_wheel">
  	<mu1 value="1.0"/>
  	<mu2 value="1.0"/>
  	<kp value="1000000.0" />
  	<kd value="1.0" />
  	<!--<fdir1 value="1 0 0"/> -->
  	<turnGravityOff>false</turnGravityOff>
  </gazebo>
    <gazebo reference="left_rear_wheel">
  	<mu1 value="1.0"/>
  	<mu2 value="1.0"/>
  	<kp value="1000000.0" />
  	<kd value="1.0" />
  	<fdir1 value="1 0 0"/>
  	<turnGravityOff>false</turnGravityOff>
  </gazebo>
  <gazebo reference="right_rear_wheel">
  	<mu1 value="1.0"/>
  	<mu2 value="1.0"/>
  	<kp value="1000000.0" />
  	<kd value="1.0" />
  	<fdir1 value="1 0 0"/>
  	<turnGravityOff>false</turnGravityOff>
  </gazebo>
  <!-- camera -->
  <gazebo reference="camera">
    <material>Gazebo/Green</material>
    <sensor name="camera1" type="camera">
      <update_rate>30.0</update_rate>
      <camera name="head">
        <horizontal_fov>1.3962634</horizontal_fov>
        <image>
          <width>800</width>
          <height>800</height>
          <format>R8G8B8</format>
        </image>
        <clip>
          <near>0.02</near>
          <far>300</far>
        </clip>
      </camera>
      <plugin filename="libgazebo_ros_camera.so" name="camera_controller">
        <alwaysOn>true</alwaysOn>
        <updateRate>0.0</updateRate>
        <cameraName>/camera</cameraName>
        <imageTopicName>image_raw</imageTopicName>
        <cameraInfoTopicName>camera_info</cameraInfoTopicName>
        <frameName>camera</frameName>
        <hackBaseline>0.07</hackBaseline>
        <distortionK1>0.0</distortionK1>
        <distortionK2>0.0</distortionK2>
        <distortionK3>0.0</distortionK3>
        <distortionT1>0.0</distortionT1>
        <distortionT2>0.0</distortionT2>
      </plugin>
    </sensor>
  </gazebo> 

  <!-- hokuyo -->
<!--  <gazebo reference="hokuyo-ust/odometry/gps-10lx">
    <sensor name="hokuyo-ust-10lx" type="ray">
      <pose>0 0 0 0 0 0</pose>
      <visualize>true</visualize>
      <update_rate>40</update_rate>
      <ray>
        <scan>
          <horizontal>
            <samples>720</samples>
            <resolution>1</resolution>
            <min_angle>-0.78</min_angle>
            <max_angle>0.78</max_angle> -->
            <!-- <min_angle>-1.570796</min_angle>
            <max_angle>1.570796</max_angle> -->
 <!--         </horizontal>
        </scan>
        <range>
          <min>0.10</min>
          <max>30.0</max>
          <resolution>0.01</resolution>
        </range>
        <noise>
          <type>gaussian</type> -->
          <!-- Noise parameters based on published spec for Hokuyo laser
               achieving "+-30mm" accuracy at range < 10m.  A mean of 0.0m and
               stddev of 0.01m will put 99.7% of samples within 0.03m of the true
               reading. -->
 <!--         <mean>0.0</mean>
          <stddev>0.01</stddev>
        </noise>
      </ray>
      <plugin filename="libgazebo_ros_laser.so" name="gazebo_ros_head_hokuyo_controller">
        <topicName>/scan_ust_10lx</topicName>
        <frameName>hokuyo-ust-10lx</frameName>
      </plugin>
    </sensor>
  </gazebo>
  <gazebo reference="hokuyo-uxm-30lx-e">
    <sensor name="hokuyo-uxm-30lx-e" type="ray">
      <pose>0 0 0 0 0 0</pose>
      <visualize>true</visualize>
      <update_rate>40</update_rate>
      <ray>
        <scan>
          <horizontal>
            <samples>720</samples>
            <resolution>1</resolution>
            <min_angle>-0.78</min_angle>
            <max_angle>0.78</max_angle> -->
            <!-- <min_angle>-1.570796</min_angle>
            <max_angle>1.570796</max_angle> -->
 <!--         </horizontal>
        </scan>
        <range>
          <min>0.10</min>
          <max>30.0</max>
          <resolution>0.01</resolution>
        </range>
        <noise>
          <type>gaussian</type> -->
          <!-- Noise parameters based on published spec for Hokuyo laser
               achieving "+-30mm" accuracy at range < 10m.  A mean of 0.0m and
               stddev of 0.01m will put 99.7% of samples within 0.03m of the true
               reading. -->
<!--          <mean>0.0</mean>
          <stddev>0.01</stddev>
        </noise>
      </ray>
      <plugin filename="libgazebo_ros_laser.so" name="gazebo_ros_head_hokuyo_controller">
        <topicName>/scan_uxm_30lx_e</topicName>
        <frameName>hokuyo-uxm-30lx-e</frameName>
      </plugin>
    </sensor>
  </gazebo> -->
  <!-- TODO: Look through logs on launch to set more params for imu, camera, and laser -->
  <gazebo>
    <plugin filename="libhector_gazebo_ros_gps.so" name="gazebo_ros_gps">
      <updateRate>5.0</updateRate>
      <bodyName>link_gps</bodyName>
      <frameId>base_link</frameId>
      <topicName>/gps/fix</topicName>
      <velocityTopicName>/gps/fix_velocity</velocityTopicName>
      <referenceLatitude>42.0</referenceLatitude>
      <referenceLongitude>-71.0</referenceLongitude>
      <referenceHeading>90</referenceHeading>
      <referenceAltitude>0</referenceAltitude>
      <offset>0 0 0</offset>
      <drift>0.000 0.000 0.00</drift>
      <gaussianNoise>0.05 0.05 0.05</gaussianNoise>
      <velocityDrift>0.000 0.000 0.000</velocityDrift>
      <velocityGaussianNoise>0.5 0.5 0.5</velocityGaussianNoise>
    </plugin>
  </gazebo>
  <!-- GPS with noise -->
  <!-- <gazebo>
    <plugin name="gazebo_ros_gps" filename="libhector_gazebo_ros_gps.so">
      <updateRate>4.0</updateRate>
      <bodyName>gps</bodyName>
      <frameId>sensor</frameId>
      <topicName>/gps/fix</topicName>
      <velocityTopicName>/gps/fix_velocity</velocityTopicName>
      <referenceLatitude>-30.06022459407145675</referenceLatitude>
      <referenceLongitude>-51.173913575780311191</referenceLongitude>
      <referenceHeading>90</referenceHeading>
      <referenceAltitude>10</referenceAltitude>
      <offset>0 0 0</offset>
      <drift>0.001 0.001 0.001</drift>
      <gaussianNoise>0.05 0.05 0.05</gaussianNoise>
      <velocityDrift>0.001 0.001 0.001</velocityDrift>
      <velocityGaussianNoise>0.5 0.5 0.5</velocityGaussianNoise>
    </plugin>
  </gazebo> -->

  <gazebo>
    <plugin filename="libhector_gazebo_ros_imu.so" name="imu_plugin">
      <updateRate>10.0</updateRate>
      <bodyName>imu</bodyName>
      <topicName>imu/data_raw</topicName>
      <serviceName>imu_service</serviceName>
      <frame_id>odom</frame_id>
      <alwaysOn>true</alwaysOn>
      <accelOffset>0.0 0.0 0.0</accelOffset>
      <accelDrift>0.0 0.0 0.0</accelDrift>
      <accelDriftFrequency>0.0 0.0 0.0</accelDriftFrequency>
      <accelGaussianNoise>0.0 0.0 0.0</accelGaussianNoise>
      <rateOffset>0.0 0.0 0.0</rateOffset>
      <rateDrift>0.0 0.0 0.0</rateDrift>
      <rateDriftFrequency>0.0 0.0 0.0</rateDriftFrequency>
      <rateGaussianNoise>0.0 0.0 0.0</rateGaussianNoise>
      <yawOffset>0.0</yawOffset>
      <yawDrift>0.0</yawDrift>
      <yawDriftFrequency>0.0</yawDriftFrequency>
      <yawGaussianNoise>0.00</yawGaussianNoise>
    </plugin>
  </gazebo> 
<!--
  <gazebo reference="imu">
    <gravity>true</gravity>
    <sensor name="imu_sensor" type="imu">
      <always_on>true</always_on>
      <update_rate>100</update_rate>
      <visualize>true</visualize>
      <topic>__default_topic__</topic>
      <plugin filename="libgazebo_ros_imu_sensor.so" name="imu_plugin">
        <topicName>imu/data_raw</topicName>
        <bodyName>imu</bodyName>
        <updateRateHZ>10.0</updateRateHZ>
        <gaussianNoise>0.0</gaussianNoise>
        <xyzOffset>0 0 0</xyzOffset>
        <rpyOffset>0 0 0</rpyOffset>
        <frameName>odom</frameName>
        <initialOrientationAsReference>false</initialOrientationAsReference>
      </plugin>
      <pose>0 0 0 0 0 0</pose>
    </sensor>
  </gazebo>-->
  <gazebo>
    <plugin filename="libhitch_plugin.so" name="hitch_control">
    </plugin>
  </gazebo>
  <link name="base_link">
    <visual>
      <geometry>
        <box size="0.01 0.01 0.01"/>
      </geometry>
    </visual>
  </link>
  <gazebo reference="base_link">
    <material>Gazebo/Grey</material>
  </gazebo>
  <!-- Chassis -->
  <link name="chassis">
    <visual>
      <origin rpy="0 0 3.14159266" scale="1 1 1" xyz="0.55 0 0"/>
      <geometry>
        <mesh filename="package://tractor_description/meshes/kubo_chassis.dae"/>
      </geometry>
    </visual>
    <collision>
      <origin xyz="0.55 0 0.25"/>
      <geometry>
        <box size="1.1 0.3 0.1"/>
      </geometry>
    </collision>
    <inertial>
      <origin xyz="0 0 -0.05"/>
      <mass value="2.788"/>
      <inertia ixx="0.0232333333333" ixy="0" ixz="0" iyy="0.283446666667" iyz="0" izz="0.302033333333"/>
    </inertial>
  </link>
  <joint name="base_link_to_chassis" type="fixed">
    <parent link="base_link"/>
    <child link="chassis"/>
  </joint>

  <!-- Hitch -->
<!--<link name="hitch">
    <visual>
      <origin rpy="1.57079633 0 -1.57079633" scale="1 1 1" xyz="0 0 0"/>-->
      <!-- <geometry>
        <box size="${chassis_length} ${chassis_width} ${chassis_height}"/>
      </geometry> -->
 <!--     <geometry>
        <mesh filename="package://tractor_description/meshes/blade.dae"/>
      </geometry>
    </visual>
    <inertial>
      <origin xyz="0 0 -0.05"/>
      <mass value="0.1"/>
      <inertia ixx="0.000833333333333" ixy="0" ixz="0" iyy="0.0101666666667" iyz="0" izz="0.0108333333333"/>
    </inertial>
  </link>
  <joint name="base_link_to_hitch" type="prismatic">
    <parent link="base_link"/>
    <child link="hitch"/>
    <limit effort="10" lower="-1" upper="1" velocity="0.1"/>
    <origin rpy="0 1.57079633 0" xyz="-0.5 0 0"/>
  </joint>
  -->
  <joint name="left_front_shock" type="prismatic">
    <parent link="chassis"/>
    <child link="left_steering_link"/>
    <origin xyz="1.2 0.4 0.25"/>
    <!-- Default: ${fr_reflect * wheelbase / 2}
                                ${lr_reflect * ((hex_hub_dist / 2) - axle_length)}
                                ${(wheel_travel / 2) - shock_z_offset}"-->
    <axis xyz="0 0 -1"/>
    <limit effort="1000000" lower="0.0" upper="0.0" velocity="1000000"/>
  </joint>
  <transmission name="left_front_shock_trans">
    <type>transmission_interface/SimpleTransmission</type>
    <joint name="left_front_shock">
      <hardwareInterface>hardware_interface/EffortJointInterface</hardwareInterface>
    </joint>
    <actuator name="left_front_shock_act">
      <!-- This hardwareInterface element exists for compatibility
             with ROS Hydro. -->
      <hardwareInterface>hardware_interface/EffortJointInterface</hardwareInterface>
      <mechanicalReduction>1</mechanicalReduction>
    </actuator>
  </transmission>
  <link name="left_steering_link">
    <inertial>
      <mass value="0.001"/>
      <inertia ixx="0.001" ixy="0" ixz="0" iyy="0.001" iyz="0" izz="0.001"/>
    </inertial>
  </link>
  <joint name="left_steering_joint" type="revolute">
    <parent link="left_steering_link"/>
    <child link="left_front_axle_carrier"/>
    <axis xyz="0 0 1"/>
    <dynamics damping="0.4"/>
    <limit effort="5649" lower="-0.785398163" upper="0.785398163" velocity="0.5"/>
  </joint>
  <transmission name="left_steering_trans">
    <type>transmission_interface/SimpleTransmission</type>
    <joint name="left_steering_joint">
    	<hardwareInterface>hardware_interface/EffortJointInterface</hardwareInterface> 
    </joint>
    <actuator name="left_steering_act">
    	<hardwareInterface>EffortJointInterface</hardwareInterface>
    	<mechanicalReduction>1</mechanicalReduction>
    </actuator>
  </transmission>



  <link name="left_front_axle_carrier">
    <inertial>
      <mass value="0.001"/>
      <inertia ixx="0.001" ixy="0" ixz="0" iyy="0.001" iyz="0" izz="0.001"/>
    </inertial>
  </link>

  <joint name="left_front_axle" type="continuous">
    <parent link="left_front_axle_carrier"/>
    <child link="left_front_wheel"/>
    <origin rpy="1.57079633 0 0"/>
    <axis xyz="0 0 -1"/>
    <limit effort="512766" velocity="2448696"/>
  </joint>
 
  <transmission name="left_front_axle_trans">
  	<type>transmission_interface/SimpleTransmission</type>
  	<joint name="left_front_axle">
      <!--<hardwareInterface>hardware_interface/VelocityJointInterface</hardwareInterface>-->
      <hardwareInterface>hardware_interface/EffortJointInterface</hardwareInterface>
  	</joint>
  	<actuator name="left_wheel_actuator">
  		<mechanicalReduction>1</mechanicalReduction>
  	<!--	<hardwareInterface>VelocityJointInterface</hardwareInterface>-->
      <hardwareInterface>EffortJointInterface</hardwareInterface>
  	</actuator>
  </transmission>

  <link name="left_front_wheel">
    <visual>
      <origin rpy="1.57079633 0 0" xyz="0 -0.0 0" scale="1 1 1" />
      <geometry>
        <mesh filename="package://tractor_description/meshes/kubo_front_tire1.dae"/>
      </geometry>
    </visual>
    <collision>
      <origin xyz="0 -0.0 0"/>
      <geometry>
        <cylinder length="0.15" radius="0.25"/>
      </geometry>
    </collision>
    <inertial>
      <mass value="0.29"/>
      <inertia ixx="0.005075" ixy="0" ixz="0" iyy="0.005075" iyz="0" izz="0.0090625"/>
    </inertial>
  </link>
  <joint name="right_front_shock" type="prismatic">
    <parent link="chassis"/>
    <child link="right_steering_link"/>
    <origin xyz="1.2 -0.4 0.25"/>
    <axis xyz="0 0 -1"/>
    <limit effort="1000000" lower="0.0" upper="0.0" velocity="1000000"/>
  </joint>
  <transmission name="right_front_shock_trans">
    <type>transmission_interface/SimpleTransmission</type>
    <joint name="right_front_shock">
      <hardwareInterface>hardware_interface/EffortJointInterface</hardwareInterface>
    </joint>
    <actuator name="right_front_shock_act">
      <!-- This hardwareInterface element exists for compatibility
             with ROS Hydro. -->
      <hardwareInterface>hardware_interface/EffortJointInterface</hardwareInterface>
      <mechanicalReduction>1</mechanicalReduction>
    </actuator>
  </transmission>
  <link name="right_steering_link">
    <inertial>
      <mass value="0.001"/>
      <inertia ixx="0.001" ixy="0" ixz="0" iyy="0.001" iyz="0" izz="0.001"/>
    </inertial>
  </link>
  <joint name="right_steering_joint" type="revolute">
    <parent link="right_steering_link"/>
    <child link="right_front_axle_carrier"/>
    <axis xyz="0 0 1"/>
    <dynamics damping="0.4"/>
    <limit effort="5649" lower="-0.785398163" upper="0.785398163" velocity="0.5"/>
  </joint>
  <transmission name="right_steering_trans">
    <type>transmission_interface/SimpleTransmission</type>
    <joint name="right_steering_joint">
      <hardwareInterface>hardware_interface/EffortJointInterface</hardwareInterface>
    </joint>
    <actuator name="right_steering_act">
      <!-- This hardwareInterface element exists for compatibility
             with ROS Hydro. -->
      <hardwareInterface>EffortJointInterface</hardwareInterface>
      <mechanicalReduction>1</mechanicalReduction>
    </actuator>
  </transmission>
  <link name="right_front_axle_carrier">
    <inertial>
      <mass value="0.001"/>
      <inertia ixx="0.001" ixy="0" ixz="0" iyy="0.001" iyz="0" izz="0.001"/>
    </inertial>
  </link>
  <!-- The left and right axles have the same axis so that identical
         rotation values cause the wheels to rotate in the same direction. -->
  <joint name="right_front_axle" type="continuous">
    <parent link="right_front_axle_carrier"/>
    <child link="right_front_wheel"/>
    <origin rpy="1.57079633 0 0"/>
    <axis xyz="0 0 -1"/>
    <limit effort="512766" velocity="2448696"/>
  </joint>
  <transmission name="right_front_axle_trans">
    <type>transmission_interface/SimpleTransmission</type>
    <joint name="right_front_axle">
      <!--<hardwareInterface>hardware_interface/VelocityJointInterface</hardwareInterface>-->
      <hardwareInterface>hardware_interface/EffortJointInterface</hardwareInterface>
    </joint>
    <actuator name="right_front_axle_act">
      <!-- This hardwareInterface element exists for compatibility
             with ROS Hydro. -->
      <!--<hardwareInterface>VelocityJointInterface</hardwareInterface>-->
      <hardwareInterface>EffortJointInterface</hardwareInterface>
      <mechanicalReduction>1</mechanicalReduction>
    </actuator>
  </transmission>
  <link name="right_front_wheel">
    <visual>
      <origin rpy="-1.57079633 0 0" xyz="0 0 0" scale="1 1 1" />
      <geometry>
        <mesh filename="package://tractor_description/meshes/kubo_front_tire1.dae"/>
      </geometry>
    </visual>
    <collision>
      <origin xyz="0 0.0 0"/>
      <geometry>
        <cylinder length="0.15" radius="0.25"/>
      </geometry>
    </collision>
    <inertial>
      <mass value="0.29"/>
      <inertia ixx="0.005075" ixy="0" ixz="0" iyy="0.005075" iyz="0" izz="0.0090625"/>
    </inertial>
  </link>
  <joint name="left_rear_shock" type="prismatic">
    <parent link="chassis"/>
    <child link="left_rear_axle_carrier"/>
    <origin xyz="0.0 0.4 0.35"/>
    <axis xyz="0 0 -1"/>
    <limit effort="1000000" lower="0.0" upper="0.0" velocity="1000000"/>
  </joint>
  <transmission name="left_rear_shock_trans">
    <type>transmission_interface/SimpleTransmission</type>
    <joint name="left_rear_shock">
      <hardwareInterface>hardware_interface/EffortJointInterface</hardwareInterface>
    </joint>
    <actuator name="left_rear_shock_act">
      <!-- This hardwareInterface element exists for compatibility
             with ROS Hydro. -->
      <hardwareInterface>hardware_interface/EffortJointInterface</hardwareInterface>
      <mechanicalReduction>1</mechanicalReduction>
    </actuator>
  </transmission>
  <link name="left_rear_axle_carrier">
    <inertial>
      <mass value="0.001"/>
      <inertia ixx="0.001" ixy="0" ixz="0" iyy="0.001" iyz="0" izz="0.001"/>
    </inertial>
  </link>
  <!-- The left and right axles have the same axis so that identical
         rotation values cause the wheels to rotate in the same direction. -->
  <joint name="left_rear_axle" type="continuous">
    <parent link="left_rear_axle_carrier"/>
    <child link="left_rear_wheel"/>
    <origin rpy="1.57079633 0 0"/>
    <axis xyz="0 0 -1"/>
    <limit effort="512766" velocity="2448696"/>
  </joint>
  <transmission name="left_rear_axle_trans">
    <type>transmission_interface/SimpleTransmission</type>
    <joint name="left_rear_axle">
      <!--<hardwareInterface>hardware_interface/VelocityJointInterface</hardwareInterface>-->
      <hardwareInterface>hardware_interface/EffortJointInterface</hardwareInterface>
    </joint>
    <actuator name="left_rear_axle_act">
      <!-- This hardwareInterface element exists for compatibility
             with ROS Hydro. -->
      <!--<hardwareInterface>VelocityJointInterface</hardwareInterface>-->
      <hardwareInterface>EffortJointInterface</hardwareInterface>
      <mechanicalReduction>1</mechanicalReduction>
    </actuator>
  </transmission>
  <link name="left_rear_wheel">
    <visual>
      <origin rpy="1.57079633 0 0" xyz="0 -0.0 0" />
      <geometry>
        <mesh filename="package://tractor_description/meshes/kubo_back_tire1.dae" scale="1 1 1"/>
      </geometry>
    </visual>
    <collision>
      <origin xyz="0 -0.0 0"/>
      <geometry>
        <cylinder length="0.2" radius="0.35"/>
      </geometry>
    </collision>
    <inertial>
      <mass value="0.29"/>
      <inertia ixx="0.00984791666667" ixy="0" ixz="0" iyy="0.00984791666667" iyz="0" izz="0.0177625"/>
    </inertial>
  </link>
  <joint name="right_rear_shock" type="prismatic">
    <parent link="chassis"/>
    <child link="right_rear_axle_carrier"/>
    <origin xyz="0.0 -0.4 0.35"/>

    <axis xyz="0 0 -1"/>
    <limit effort="1000000" lower="0.0" upper="0.0" velocity="1000000"/>
  </joint>
  <transmission name="right_rear_shock_trans">
    <type>transmission_interface/SimpleTransmission</type>
    <joint name="right_rear_shock">
      <hardwareInterface>hardware_interface/EffortJointInterface</hardwareInterface>
    </joint>
    <actuator name="right_rear_shock_act">
      <!-- This hardwareInterface element exists for compatibility
             with ROS Hydro. -->
      <hardwareInterface>hardware_interface/EffortJointInterface</hardwareInterface>
      <mechanicalReduction>1</mechanicalReduction>
    </actuator>
  </transmission>
  <link name="right_rear_axle_carrier">
    <inertial>
      <mass value="0.001"/>
      <inertia ixx="0.001" ixy="0" ixz="0" iyy="0.001" iyz="0" izz="0.001"/>
    </inertial>
  </link>
  <!-- The left and right axles have the same axis so that identical
         rotation values cause the wheels to rotate in the same direction. -->
  <joint name="right_rear_axle" type="continuous">
    <parent link="right_rear_axle_carrier"/>
    <child link="right_rear_wheel"/>
    <origin rpy="1.57079633 0 0"/>
    <axis xyz="0 0 -1"/>
    <limit effort="512766" velocity="2448696"/>
  </joint>
  <transmission name="right_rear_axle_trans">
    <type>transmission_interface/SimpleTransmission</type>
    <joint name="right_rear_axle">
      <!--<hardwareInterface>hardware_interface/VelocityJointInterface</hardwareInterface>-->
      <hardwareInterface>hardware_interface/EffortJointInterface</hardwareInterface>
    </joint>
    <actuator name="right_rear_axle_act">
      <!--<hardwareInterface>VelocityJointInterface</hardwareInterface>-->
      <hardwareInterface>EffortJointInterface</hardwareInterface>
      <mechanicalReduction>1</mechanicalReduction>
    </actuator>
  </transmission>
  <link name="right_rear_wheel">
    <visual>
      <origin rpy="-1.57079633 0 0" xyz="0 0.0 0" scale="1 1 1"/>
      <geometry>
        <mesh filename="package://tractor_description/meshes/kubo_back_tire1.dae"/>
      </geometry>
      <material name="black">
         <color rgba="0 0 0 1"/>
      </material>
    </visual>
    <collision>
      <origin xyz="0 0.0 0"/>
      <geometry>
        <cylinder length="0.2" radius="0.35"/>
      </geometry>
    </collision>
    <inertial>
      <mass value="0.29"/>
      <inertia ixx="0.00984791666667" ixy="0" ixz="0" iyy="0.00984791666667" iyz="0" izz="0.0177625"/>
    </inertial>
  </link>

  <link name="camera">
    <collision>
      <origin rpy="0 0 0" xyz="0 0 0"/>
      <geometry>
        <box size="0.05 0.05 0.05"/>
      </geometry>
    </collision>
    <visual>
      <origin rpy="0 0 0" xyz="0 0 0"/>
      <geometry>
        <box size="0.05 0.05 0.05"/>
      </geometry>
    </visual>
    <inertial>
      <mass value="0.1"/>
      <origin rpy="0 0 0" xyz="0 0 0"/>
      <box_inertia m="0.1" x="0.1" y="0.1" z="0.1"/>
      <inertia ixx="1e-6" ixy="0" ixz="0" iyy="1e-6" iyz="0" izz="1e-6"/>
    </inertial>
  </link>
  <joint name="camera_joint" type="fixed">
    <axis xyz="0 1 0"/>
    <origin rpy="0 0 0" xyz="2.08 0 1.04"/>
    <parent link="base_link"/>
    <child link="camera"/>
  </joint>
  
  <link name="imu">
    <collision>
      <origin rpy="0 0 0" xyz="0 0 0"/>
      <geometry>
        <box size="0.05 0.05 0.05"/>
        <!-- CHANGE LATER-->
      </geometry>
    </collision>
    <visual>
      <origin rpy="0 0 0" xyz="0 0 0"/>
      <geometry>
        <box size="0.05 0.05 0.05"/>
      </geometry>
    </visual>
    <inertial>
      <mass value="0.1"/>
      <origin rpy="0 0 0" xyz="0 0 0"/>
      <box_inertia m="0.1" x="0.1" y="0.1" z="0.1"/>
      <inertia ixx="1e-6" ixy="0" ixz="0" iyy="1e-6" iyz="0" izz="1e-6"/>
    </inertial>
  </link>
  <joint name="imu_joint" type="fixed">
    <axis xyz="0 1 0"/>
    <origin rpy="0 0 0" xyz="-0.3 0 1"/>
    <parent link="base_link"/>
    <child link="imu"/>
  </joint>
  <link name="link_gps">
    <collision>
      <origin rpy="0 0 0" xyz="0 0 0"/>
      <geometry>
        <box size="0.05 0.05 0.05"/>
        <!-- CHANGE LATER-->
      </geometry>
    </collision>
    <visual>
      <origin rpy="0 0 0" xyz="0 0 0"/>
      <geometry>
        <box size="0.05 0.05 0.05"/>
      </geometry>
    </visual>
    <inertial>
      <mass value="0.1"/>
      <origin rpy="0 0 0" xyz="0 0 0"/>
      <box_inertia m="0.1" x="0.1" y="0.1" z="0.1"/>
      <inertia ixx="1e-6" ixy="0" ixz="0" iyy="1e-6" iyz="0" izz="1e-6"/>
    </inertial>
  </link>
  <joint name="link_gps_joint" type="fixed">
    <axis xyz="0 1 0"/>
    <origin rpy="0 0 0" xyz="0 0 2.0"/>
    <parent link="base_link"/>
    <child link="link_gps"/>
  </joint>
  <!-- TODO: Update specs -->
  <!--
  <joint name="lidarx_base_mount_joint" type="fixed">
    <origin rpy="0 0.5 0" xyz="2.5 0 1.25"/>
    <parent link="base_link"/>
    <child link="lidarx_base_link"/>
  </joint>
  <link name="lidarx_base_link">
    <inertial>
      <mass value="0.83"/>
      <origin xyz="0 0 0.03585"/>
      <inertia ixx="0.000908059425" ixy="0" ixz="0" iyy="0.000908059425" iyz="0" izz="0.0011049624"/>
    </inertial>
    <visual>
      <geometry>
        <mesh filename="package://velodyne_description/meshes/VLP16_base_1.dae"/>
      </geometry>
    </visual>
    <visual>
      <geometry>
        <mesh filename="package://velodyne_description/meshes/VLP16_base_2.dae"/>
      </geometry>
    </visual>
    <collision>
      <origin rpy="0 0 0" xyz="0 0 0.03585"/>
      <geometry>
        <cylinder length="0.0717" radius="0.0516"/>
      </geometry>
    </collision>
  </link>
  <joint name="lidarx_base_scan_joint" type="fixed">
    <origin rpy="0 0 0" xyz="0 0 0.0377"/>
    <parent link="lidarx_base_link"/>
    <child link="lidarx"/>
  </joint>
  <link name="lidarx">
    <inertial>
      <mass value="0.01"/>
      <origin xyz="0 0 0"/>
      <inertia ixx="1e-7" ixy="0" ixz="0" iyy="1e-7" iyz="0" izz="1e-7"/>
    </inertial>
    <visual>
      <origin xyz="0 0 -0.0377"/>
      <geometry>
        <mesh filename="package://velodyne_description/meshes/VLP16_scan.dae"/>
      </geometry>
    </visual>
  </link> -->
  <!-- Gazebo requires the velodyne_gazebo_plugins package -->
<!--  <gazebo reference="lidarx">
    <sensor name="lidarx-lidarx" type="ray">
      <pose>0 0 0 0 0 0</pose>
      <visualize>false</visualize>
      <update_rate>10</update_rate>
      <ray>
        <scan>
          <horizontal>
            <samples>440</samples>
            <resolution>1</resolution>
            <min_angle>-3.14159265359</min_angle>
            <max_angle>3.14159265359</max_angle>
          </horizontal>
          <vertical>
            <samples>16</samples>
            <resolution>1</resolution>
            <min_angle>-0.349065850399</min_angle>
            <max_angle> 0.349065850399</max_angle>
          </vertical>
        </scan>
        <range>
          <min>0.3</min>
          <max>131.0</max>
          <resolution>0.001</resolution>
        </range>
        <noise>
          <type>gaussian</type>
          <mean>0.0</mean>
          <stddev>0.0</stddev>
        </noise>
      </ray>
      <plugin filename="libgazebo_ros_velodyne_laser.so" name="gazebo_ros_laser_controller">
        <topicName>/lidarx_points</topicName>
        <frameName>lidarx</frameName>
        <min_range>0.9</min_range>
        <max_range>130.0</max_range>
        <gaussianNoise>0.008</gaussianNoise>
      </plugin>
    </sensor>
  </gazebo> -->
  <!-- Hokuyo Laser -->
  <!-- Using mesh example
  <link name="hokuyo">
    <collision>
      <origin xyz="0 0 0" rpy="0 0 0"/>
      <geometry>
    <box size="0.1 0.1 0.1"/>
      </geometry>
    </collision>

    <visual>
      <origin xyz="0 0 0" rpy="0 0 0"/>
      <geometry>
        <mesh filename="package://tractor_sim_description/meshes/hokuyo.dae"/>
      </geometry>
    </visual>

    <inertial>
      <mass value="1e-5" />
      <origin xyz="0 0 0" rpy="0 0 0"/>
      <inertia ixx="1e-6" ixy="0" ixz="0" iyy="1e-6" iyz="0" izz="1e-6" />
    </inertial>
  </link>

  <joint name="hokuyo_joint" type="fixed">
    <axis xyz="0 1 0" />
    <origin xyz=".15 0 .6" rpy="0 -.1 0"/>
    <parent link="chassis"/>
    <child link="hokuyo"/>
  </joint>
-->
</robot>

