<sdf version='1.7'>
  <world name='my_world'>
    <model name='ground 1'>
      <static>1</static>
      <link name='link'>
        <collision name='collision'>
          <geometry>
            <plane>
              <normal>0 0 1</normal>
              <size>20 20</size>
            </plane>
          </geometry>
          <surface>
            <contact>
              <collide_bitmask>65535</collide_bitmask>
              <ode/>
            </contact>
            <friction>
              <ode>
                <mu>50</mu>
                <mu2>50</mu2>
              </ode>
              <torsional>
                <ode/>
              </torsional>
            </friction>
            <bounce/>
          </surface>
          <max_contacts>10</max_contacts>
        </collision>
        <visual name='visual'>
          <cast_shadows>0</cast_shadows>
          <geometry>
            <plane>
              <normal>0 0 1</normal>
              <size>20 20</size>
            </plane>
          </geometry>
          <material>
            <script>
              <uri>model://ground_grass_1/materials/scripts</uri>
              <uri>model://ground_grass_1/materials/textures</uri>
              <name>GrassGround</name>
            </script>
          </material>
        </visual>
        <self_collide>0</self_collide>
        <enable_wind>0</enable_wind>
        <kinematic>0</kinematic>
      </link>
      <pose>10 10 0 0 -0 0</pose>
    </model>
    <model name='ground 2'>
      <static>1</static>
      <link name='link'>
        <collision name='collision'>
          <geometry>
            <plane>
              <normal>0 0 1</normal>
              <size>20 20</size>
            </plane>
          </geometry>
          <surface>
            <contact>
              <collide_bitmask>65535</collide_bitmask>
              <ode/>
            </contact>
            <friction>
              <ode>
                <mu>100</mu>
                <mu2>50</mu2>
              </ode>
              <torsional>
                <ode/>
              </torsional>
            </friction>
            <bounce/>
          </surface>
          <max_contacts>10</max_contacts>
        </collision>
        <visual name='visual'>
          <cast_shadows>0</cast_shadows>
          <geometry>
            <plane>
              <normal>0 0 1</normal>
              <size>20 20</size>
            </plane>
          </geometry>
          <material>
            <script>
              <uri>model://ground_grass_2/materials/scripts</uri>
              <uri>model://ground_grass_2/materials/textures</uri>
              <name>GrassGround</name>
            </script>
          </material>
        </visual>
        <self_collide>0</self_collide>
        <enable_wind>0</enable_wind>
        <kinematic>0</kinematic>
      </link>
      <pose>10 -10 0 0 -0 0</pose>
    </model>
    <model name='ground 3'>
      <static>1</static>
      <link name='link'>
        <collision name='collision'>
          <geometry>
            <plane>
              <normal>0 0 1</normal>
              <size>20 20</size>
            </plane>
          </geometry>
          <surface>
            <contact>
              <collide_bitmask>65535</collide_bitmask>
              <ode/>
            </contact>
            <friction>
              <ode>
                <mu>100</mu>
                <mu2>50</mu2>
              </ode>
              <torsional>
                <ode/>
              </torsional>
            </friction>
            <bounce/>
          </surface>
          <max_contacts>10</max_contacts>
        </collision>
        <visual name='visual'>
          <cast_shadows>0</cast_shadows>
          <geometry>
            <plane>
              <normal>0 0 1</normal>
              <size>20 20</size>
            </plane>
          </geometry>
          <material>
            <script>
              <uri>model://ground_grass_2/materials/scripts</uri>
              <uri>model://ground_grass_2/materials/textures</uri>
              <name>GrassGround</name>
            </script>
          </material>
        </visual>
        <self_collide>0</self_collide>
        <enable_wind>0</enable_wind>
        <kinematic>0</kinematic>
      </link>
      <pose>-10 10 0 0 -0 0</pose>
    </model>
    <model name='ground 4'>
      <static>1</static>
      <link name='link'>
        <collision name='collision'>
          <geometry>
            <plane>
              <normal>0 0 1</normal>
              <size>20 20</size>
            </plane>
          </geometry>
          <surface>
            <contact>
              <collide_bitmask>65535</collide_bitmask>
              <ode/>
            </contact>
            <friction>
              <ode>
                <mu>50</mu>
                <mu2>50</mu2>
              </ode>
              <torsional>
                <ode/>
              </torsional>
            </friction>
            <bounce/>
          </surface>
          <max_contacts>10</max_contacts>
        </collision>
        <visual name='visual'>
          <cast_shadows>0</cast_shadows>
          <geometry>
            <plane>
              <normal>0 0 1</normal>
              <size>20 20</size>
            </plane>
          </geometry>
          <material>
            <script>
              <uri>model://ground_grass_1/materials/scripts</uri>
              <uri>model://ground_grass_1/materials/textures</uri>
              <name>GrassGround</name>
            </script>
          </material>
        </visual>
        <self_collide>0</self_collide>
        <enable_wind>0</enable_wind>
        <kinematic>0</kinematic>
      </link>
      <pose>-10 -10 0 0 -0 0</pose>
    </model>
    <model name='ground 5'>
      <static>1</static>
      <link name='link'>
        <collision name='collision'>
          <geometry>
            <plane>
              <normal>0 0 1</normal>
              <size>20 20</size>
            </plane>
          </geometry>
          <surface>
            <contact>
              <collide_bitmask>65535</collide_bitmask>
              <ode/>
            </contact>
            <friction>
              <ode>
                <mu>40</mu>
                <mu2>40</mu2>
              </ode>
              <torsional>
                <ode/>
              </torsional>
            </friction>
            <bounce/>
          </surface>
          <max_contacts>10</max_contacts>
        </collision>
        <visual name='visual'>
          <cast_shadows>0</cast_shadows>
          <geometry>
            <plane>
              <normal>0 0 1</normal>
              <size>20 20</size>
            </plane>
          </geometry>
          <material>
            <script>
              <uri>model://ground_grass_3/materials/scripts</uri>
              <uri>model://ground_grass_3/materials/textures</uri>
              <name>GrassGround</name>
            </script>
          </material>
        </visual>
        <self_collide>0</self_collide>
        <enable_wind>0</enable_wind>
        <kinematic>0</kinematic>
      </link>
      <pose>30 10 0 0 -0 0</pose>
    </model>
    <model name='ground 6'>
      <static>1</static>
      <link name='link'>
        <collision name='collision'>
          <geometry>
            <plane>
              <normal>0 0 1</normal>
              <size>20 20</size>
            </plane>
          </geometry>
          <surface>
            <contact>
              <collide_bitmask>65535</collide_bitmask>
              <ode/>
            </contact>
            <friction>
              <ode>
                <mu>100</mu>
                <mu2>50</mu2>
              </ode>
              <torsional>
                <ode/>
              </torsional>
            </friction>
            <bounce/>
          </surface>
          <max_contacts>10</max_contacts>
        </collision>
        <visual name='visual'>
          <cast_shadows>0</cast_shadows>
          <geometry>
            <plane>
              <normal>0 0 1</normal>
              <size>20 20</size>
            </plane>
          </geometry>
          <material>
            <script>
              <uri>model://ground_grass_2/materials/scripts</uri>
              <uri>model://ground_grass_2/materials/textures</uri>
              <name>GrassGround</name>
            </script>
          </material>
        </visual>
        <self_collide>0</self_collide>
        <enable_wind>0</enable_wind>
        <kinematic>0</kinematic>
      </link>
      <pose>30 -10 0 0 -0 0</pose>
    </model>
    <model name='ground 7'>
      <static>1</static>
      <link name='link'>
        <collision name='collision'>
          <geometry>
            <plane>
              <normal>0 0 1</normal>
              <size>20 20</size>
            </plane>
          </geometry>
          <surface>
            <contact>
              <collide_bitmask>65535</collide_bitmask>
              <ode/>
            </contact>
            <friction>
              <ode>
                <mu>50</mu>
                <mu2>50</mu2>
              </ode>
              <torsional>
                <ode/>
              </torsional>
            </friction>
            <bounce/>
          </surface>
          <max_contacts>10</max_contacts>
        </collision>
        <visual name='visual'>
          <cast_shadows>0</cast_shadows>
          <geometry>
            <plane>
              <normal>0 0 1</normal>
              <size>20 20</size>
            </plane>
          </geometry>
          <material>
            <script>
              <uri>model://ground_grass_1/materials/scripts</uri>
              <uri>model://ground_grass_1/materials/textures</uri>
              <name>GrassGround</name>
            </script>
          </material>
        </visual>
        <self_collide>0</self_collide>
        <enable_wind>0</enable_wind>
        <kinematic>0</kinematic>
      </link>
      <pose>50 10 0 0 -0 0</pose>
    </model>
    <model name='ground 8'>
      <static>1</static>
      <link name='link'>
        <collision name='collision'>
          <geometry>
            <plane>
              <normal>0 0 1</normal>
              <size>20 20</size>
            </plane>
          </geometry>
          <surface>
            <contact>
              <collide_bitmask>65535</collide_bitmask>
              <ode/>
            </contact>
            <friction>
              <ode>
                <mu>50</mu>
                <mu2>50</mu2>
              </ode>
              <torsional>
                <ode/>
              </torsional>
            </friction>
            <bounce/>
          </surface>
          <max_contacts>10</max_contacts>
        </collision>
        <visual name='visual'>
          <cast_shadows>0</cast_shadows>
          <geometry>
            <plane>
              <normal>0 0 1</normal>
              <size>20 20</size>
            </plane>
          </geometry>
          <material>
            <script>
              <uri>model://ground_grass_1/materials/scripts</uri>
              <uri>model://ground_grass_1/materials/textures</uri>
              <name>GrassGround</name>
            </script>
          </material>
        </visual>
        <self_collide>0</self_collide>
        <enable_wind>0</enable_wind>
        <kinematic>0</kinematic>
      </link>
      <pose>50 -10 0 0 -0 0</pose>
    </model>
    <model name='ground 9'>
      <static>1</static>
      <link name='link'>
        <collision name='collision'>
          <geometry>
            <plane>
              <normal>0 0 1</normal>
              <size>20 20</size>
            </plane>
          </geometry>
          <surface>
            <contact>
              <collide_bitmask>65535</collide_bitmask>
              <ode/>
            </contact>
            <friction>
              <ode>
                <mu>100</mu>
                <mu2>50</mu2>
              </ode>
              <torsional>
                <ode/>
              </torsional>
            </friction>
            <bounce/>
          </surface>
          <max_contacts>10</max_contacts>
        </collision>
        <visual name='visual'>
          <cast_shadows>0</cast_shadows>
          <geometry>
            <plane>
              <normal>0 0 1</normal>
              <size>20 20</size>
            </plane>
          </geometry>
          <material>
            <script>
              <uri>model://ground_grass_2/materials/scripts</uri>
              <uri>model://ground_grass_2/materials/textures</uri>
              <name>GrassGround</name>
            </script>
          </material>
        </visual>
        <self_collide>0</self_collide>
        <enable_wind>0</enable_wind>
        <kinematic>0</kinematic>
      </link>
      <pose>70 10 0 0 -0 0</pose>
    </model>
    <model name='ground 10'>
      <static>1</static>
      <link name='link'>
        <collision name='collision'>
          <geometry>
            <plane>
              <normal>0 0 1</normal>
              <size>20 20</size>
            </plane>
          </geometry>
          <surface>
            <contact>
              <collide_bitmask>65535</collide_bitmask>
              <ode/>
            </contact>
            <friction>
              <ode>
                <mu>100</mu>
                <mu2>50</mu2>
              </ode>
              <torsional>
                <ode/>
              </torsional>
            </friction>
            <bounce/>
          </surface>
          <max_contacts>10</max_contacts>
        </collision>
        <visual name='visual'>
          <cast_shadows>0</cast_shadows>
          <geometry>
            <plane>
              <normal>0 0 1</normal>
              <size>20 20</size>
            </plane>
          </geometry>
          <material>
            <script>
              <uri>model://ground_grass_2/materials/scripts</uri>
              <uri>model://ground_grass_2/materials/textures</uri>
              <name>GrassGround</name>
            </script>
          </material>
        </visual>
        <self_collide>0</self_collide>
        <enable_wind>0</enable_wind>
        <kinematic>0</kinematic>
      </link>
      <pose>70 -10 0 0 -0 0</pose>
    </model>
    <light name='sun' type='directional'>
      <cast_shadows>1</cast_shadows>
      <pose>0 0 10 0 -0 0</pose>
      <diffuse>0.8 0.8 0.8 1</diffuse>
      <specular>0.2 0.2 0.2 1</specular>
      <attenuation>
        <range>1000</range>
        <constant>0.9</constant>
        <linear>0.01</linear>
        <quadratic>0.001</quadratic>
      </attenuation>
      <direction>-0.5 0.1 -0.9</direction>
      <spot>
        <inner_angle>0</inner_angle>
        <outer_angle>0</outer_angle>
        <falloff>0</falloff>
      </spot>
    </light>
    <gravity>0 0 -9.8</gravity>
    <magnetic_field>6e-06 2.3e-05 -4.2e-05</magnetic_field>
    <atmosphere type='adiabatic'/>
    <physics type='ode'>
      <max_step_size>0.001</max_step_size>
      <real_time_factor>1</real_time_factor>
      <real_time_update_rate>1000</real_time_update_rate>
    </physics>
    <scene>
      <ambient>0.4 0.4 0.4 1</ambient>
      <background>0.7 0.7 0.7 1</background>
      <shadows>1</shadows>
    </scene>
    <wind/>
    <spherical_coordinates>
      <surface_model>EARTH_WGS84</surface_model>
      <latitude_deg>0</latitude_deg>
      <longitude_deg>0</longitude_deg>
      <elevation>0</elevation>
      <heading_deg>0</heading_deg>
    </spherical_coordinates>
    <model name='lawn_tractor'>
      <link name='base_link'>
        <inertial>
          <pose>0.057642 0 0.085687 0 -0 0</pose>
          <mass>3.088</mass>
          <inertia>
            <ixx>0.615694</ixx>
            <ixy>0</ixy>
            <ixz>-0.171068</ixz>
            <iyy>1.30729</iyy>
            <iyz>0</iyz>
            <izz>0.733416</izz>
          </inertia>
        </inertial>
        <collision name='base_link_fixed_joint_lump__chassis_collision'>
          <pose>0.55 0 0.25 0 -0 0</pose>
          <geometry>
            <box>
              <size>1.1 0.3 0.1</size>
            </box>
          </geometry>
          <max_contacts>10</max_contacts>
          <surface>
            <contact>
              <ode/>
            </contact>
            <bounce/>
            <friction>
              <torsional>
                <ode/>
              </torsional>
              <ode/>
            </friction>
          </surface>
        </collision>
        <collision name='base_link_fixed_joint_lump__camera_collision_1'>
          <pose>2.08 0 1.04 0 -0 0</pose>
          <geometry>
            <box>
              <size>0.05 0.05 0.05</size>
            </box>
          </geometry>
          <surface>
            <contact>
              <ode/>
            </contact>
            <friction>
              <ode/>
              <torsional>
                <ode/>
              </torsional>
            </friction>
            <bounce/>
          </surface>
          <max_contacts>10</max_contacts>
        </collision>
        <collision name='base_link_fixed_joint_lump__imu_collision_2'>
          <pose>-0.3 0 1 0 -0 0</pose>
          <geometry>
            <box>
              <size>0.05 0.05 0.05</size>
            </box>
          </geometry>
          <max_contacts>10</max_contacts>
          <surface>
            <contact>
              <ode/>
            </contact>
            <bounce/>
            <friction>
              <torsional>
                <ode/>
              </torsional>
              <ode/>
            </friction>
          </surface>
        </collision>
        <collision name='base_link_fixed_joint_lump__link_gps_collision_3'>
          <pose>0 0 2 0 -0 0</pose>
          <geometry>
            <box>
              <size>0.05 0.05 0.05</size>
            </box>
          </geometry>
          <max_contacts>10</max_contacts>
          <surface>
            <contact>
              <ode/>
            </contact>
            <bounce/>
            <friction>
              <torsional>
                <ode/>
              </torsional>
              <ode/>
            </friction>
          </surface>
        </collision>
        <visual name='base_link_visual'>
          <pose>0 0 0 0 -0 0</pose>
          <geometry>
            <box>
              <size>0.01 0.01 0.01</size>
            </box>
          </geometry>
          <material>
            <script>
              <name>Gazebo/Grey</name>
              <uri>file://media/materials/scripts/gazebo.material</uri>
            </script>
          </material>
        </visual>
        <visual name='base_link_fixed_joint_lump__chassis_visual_1'>
          <pose>0.55 0 0 0 0 -3.14159</pose>
          <geometry>
            <mesh>
              <scale>1 1 1</scale>
              <uri>/home/ducthang/agribot/src/tractor/tractor_description/meshes/kubo_chassis.dae</uri>
            </mesh>
          </geometry>
        </visual>
        <visual name='base_link_fixed_joint_lump__camera_visual_2'>
          <pose>2.08 0 1.04 0 -0 0</pose>
          <geometry>
            <box>
              <size>0.05 0.05 0.05</size>
            </box>
          </geometry>
          <material>
            <script>
              <name>Gazebo/Green</name>
              <uri>file://media/materials/scripts/gazebo.material</uri>
            </script>
          </material>
        </visual>
        <visual name='base_link_fixed_joint_lump__imu_visual_3'>
          <pose>-0.3 0 1 0 -0 0</pose>
          <geometry>
            <box>
              <size>0.05 0.05 0.05</size>
            </box>
          </geometry>
        </visual>
        <visual name='base_link_fixed_joint_lump__link_gps_visual_4'>
          <pose>0 0 2 0 -0 0</pose>
          <geometry>
            <box>
              <size>0.05 0.05 0.05</size>
            </box>
          </geometry>
        </visual>
        <velocity_decay/>
        <gravity>1</gravity>
        <velocity_decay/>
        <sensor name='camera1' type='camera'>
          <update_rate>30</update_rate>
          <camera name='head'>
            <horizontal_fov>1.39626</horizontal_fov>
            <image>
              <width>800</width>
              <height>800</height>
              <format>R8G8B8</format>
            </image>
            <clip>
              <near>0.02</near>
              <far>300</far>
            </clip>
          </camera>
          <plugin name='camera_controller' filename='libgazebo_ros_camera.so'>
            <alwaysOn>1</alwaysOn>
            <updateRate>0.0</updateRate>
            <cameraName>/camera</cameraName>
            <imageTopicName>image_raw</imageTopicName>
            <cameraInfoTopicName>camera_info</cameraInfoTopicName>
            <frameName>camera</frameName>
            <hackBaseline>0.07</hackBaseline>
            <distortionK1>0.0</distortionK1>
            <distortionK2>0.0</distortionK2>
            <distortionK3>0.0</distortionK3>
            <distortionT1>0.0</distortionT1>
            <distortionT2>0.0</distortionT2>
            <robotNamespace>/</robotNamespace>
          </plugin>
          <pose>2.08 0 1.04 0 -0 0</pose>
        </sensor>
        <self_collide>0</self_collide>
        <enable_wind>0</enable_wind>
        <kinematic>0</kinematic>
      </link>
      <joint name='left_front_shock' type='prismatic'>
        <pose relative_to='base_link'>1.2 0.4 0.25 0 -0 0</pose>
        <parent>base_link</parent>
        <child>left_steering_link</child>
        <axis>
          <xyz>0 0 -1</xyz>
          <limit>
            <lower>0</lower>
            <upper>0</upper>
            <effort>1e+06</effort>
            <velocity>1e+06</velocity>
          </limit>
          <dynamics>
            <spring_reference>0</spring_reference>
            <spring_stiffness>0</spring_stiffness>
          </dynamics>
        </axis>
      </joint>
      <link name='left_steering_link'>
        <pose relative_to='left_front_shock'>0 0 0 0 -0 0</pose>
        <inertial>
          <pose>0 0 0 0 -0 0</pose>
          <mass>0.001</mass>
          <inertia>
            <ixx>0.001</ixx>
            <ixy>0</ixy>
            <ixz>0</ixz>
            <iyy>0.001</iyy>
            <iyz>0</iyz>
            <izz>0.001</izz>
          </inertia>
        </inertial>
        <self_collide>0</self_collide>
        <enable_wind>0</enable_wind>
        <kinematic>0</kinematic>
      </link>
      <joint name='left_steering_joint' type='revolute'>
        <pose relative_to='left_steering_link'>0 0 0 0 -0 0</pose>
        <parent>left_steering_link</parent>
        <child>left_front_axle_carrier</child>
        <axis>
          <xyz>0 0 1</xyz>
          <limit>
            <lower>-0.785398</lower>
            <upper>0.785398</upper>
            <effort>5649</effort>
            <velocity>0.5</velocity>
          </limit>
          <dynamics>
            <damping>0.4</damping>
            <friction>0</friction>
            <spring_reference>0</spring_reference>
            <spring_stiffness>0</spring_stiffness>
          </dynamics>
        </axis>
      </joint>
      <link name='left_front_axle_carrier'>
        <pose relative_to='left_steering_joint'>0 0 0 0 -0 0</pose>
        <inertial>
          <pose>0 0 0 0 -0 0</pose>
          <mass>0.001</mass>
          <inertia>
            <ixx>0.001</ixx>
            <ixy>0</ixy>
            <ixz>0</ixz>
            <iyy>0.001</iyy>
            <iyz>0</iyz>
            <izz>0.001</izz>
          </inertia>
        </inertial>
        <self_collide>0</self_collide>
        <enable_wind>0</enable_wind>
        <kinematic>0</kinematic>
      </link>
      <joint name='left_front_axle' type='revolute'>
        <pose relative_to='left_front_axle_carrier'>0 0 0 1.5708 -0 0</pose>
        <parent>left_front_axle_carrier</parent>
        <child>left_front_wheel</child>
        <axis>
          <xyz>0 0 -1</xyz>
          <limit>
            <lower>-1e+16</lower>
            <upper>1e+16</upper>
          </limit>
          <dynamics>
            <spring_reference>0</spring_reference>
            <spring_stiffness>0</spring_stiffness>
          </dynamics>
        </axis>
      </joint>
      <link name='left_front_wheel'>
        <pose relative_to='left_front_axle'>0 0 0 0 -0 0</pose>
        <inertial>
          <pose>0 0 0 0 -0 0</pose>
          <mass>0.29</mass>
          <inertia>
            <ixx>0.005075</ixx>
            <ixy>0</ixy>
            <ixz>0</ixz>
            <iyy>0.005075</iyy>
            <iyz>0</iyz>
            <izz>0.0090625</izz>
          </inertia>
        </inertial>
        <collision name='left_front_wheel_collision'>
          <pose>0 0 0 0 -0 0</pose>
          <geometry>
            <cylinder>
              <length>0.15</length>
              <radius>0.25</radius>
            </cylinder>
          </geometry>
          <surface>
            <contact>
              <ode>
                <kp>1e+06</kp>
                <kd>1</kd>
              </ode>
            </contact>
            <friction>
              <ode>
                <mu>1</mu>
                <mu2>1</mu2>
              </ode>
              <torsional>
                <ode/>
              </torsional>
            </friction>
            <bounce/>
          </surface>
          <max_contacts>10</max_contacts>
        </collision>
        <visual name='left_front_wheel_visual'>
          <pose>0 0 0 1.5708 -0 0</pose>
          <geometry>
            <mesh>
              <scale>1 1 1</scale>
              <uri>/home/ducthang/agribot/src/tractor/tractor_description/meshes/kubo_front_tire1.dae</uri>
            </mesh>
          </geometry>
        </visual>
        <gravity>1</gravity>
        <velocity_decay/>
        <self_collide>0</self_collide>
        <enable_wind>0</enable_wind>
        <kinematic>0</kinematic>
      </link>
      <joint name='left_rear_shock' type='prismatic'>
        <pose relative_to='base_link'>0 0.4 0.35 0 -0 0</pose>
        <parent>base_link</parent>
        <child>left_rear_axle_carrier</child>
        <axis>
          <xyz>0 0 -1</xyz>
          <limit>
            <lower>0</lower>
            <upper>0</upper>
            <effort>1e+06</effort>
            <velocity>1e+06</velocity>
          </limit>
          <dynamics>
            <spring_reference>0</spring_reference>
            <spring_stiffness>0</spring_stiffness>
          </dynamics>
        </axis>
      </joint>
      <link name='left_rear_axle_carrier'>
        <pose relative_to='left_rear_shock'>0 0 0 0 -0 0</pose>
        <inertial>
          <pose>0 0 0 0 -0 0</pose>
          <mass>0.001</mass>
          <inertia>
            <ixx>0.001</ixx>
            <ixy>0</ixy>
            <ixz>0</ixz>
            <iyy>0.001</iyy>
            <iyz>0</iyz>
            <izz>0.001</izz>
          </inertia>
        </inertial>
        <self_collide>0</self_collide>
        <enable_wind>0</enable_wind>
        <kinematic>0</kinematic>
      </link>
      <joint name='left_rear_axle' type='revolute'>
        <pose relative_to='left_rear_axle_carrier'>0 0 0 1.5708 -0 0</pose>
        <parent>left_rear_axle_carrier</parent>
        <child>left_rear_wheel</child>
        <axis>
          <xyz>0 0 -1</xyz>
          <limit>
            <lower>-1e+16</lower>
            <upper>1e+16</upper>
          </limit>
          <dynamics>
            <spring_reference>0</spring_reference>
            <spring_stiffness>0</spring_stiffness>
          </dynamics>
        </axis>
      </joint>
      <link name='left_rear_wheel'>
        <pose relative_to='left_rear_axle'>0 0 0 0 -0 0</pose>
        <inertial>
          <pose>0 0 0 0 -0 0</pose>
          <mass>0.29</mass>
          <inertia>
            <ixx>0.00984792</ixx>
            <ixy>0</ixy>
            <ixz>0</ixz>
            <iyy>0.00984792</iyy>
            <iyz>0</iyz>
            <izz>0.0177625</izz>
          </inertia>
        </inertial>
        <collision name='left_rear_wheel_collision'>
          <pose>0 0 0 0 -0 0</pose>
          <geometry>
            <cylinder>
              <length>0.2</length>
              <radius>0.35</radius>
            </cylinder>
          </geometry>
          <surface>
            <contact>
              <ode>
                <kp>1e+06</kp>
                <kd>1</kd>
              </ode>
            </contact>
            <friction>
              <ode>
                <mu>1</mu>
                <mu2>1</mu2>
                <fdir1>1 0 0</fdir1>
              </ode>
              <torsional>
                <ode/>
              </torsional>
            </friction>
            <bounce/>
          </surface>
          <max_contacts>10</max_contacts>
        </collision>
        <visual name='left_rear_wheel_visual'>
          <pose>0 0 0 1.5708 -0 0</pose>
          <geometry>
            <mesh>
              <scale>1 1 1</scale>
              <uri>/home/ducthang/agribot/src/tractor/tractor_description/meshes/kubo_back_tire1.dae</uri>
            </mesh>
          </geometry>
        </visual>
        <gravity>1</gravity>
        <velocity_decay/>
        <self_collide>0</self_collide>
        <enable_wind>0</enable_wind>
        <kinematic>0</kinematic>
      </link>
      <joint name='right_front_shock' type='prismatic'>
        <pose relative_to='base_link'>1.2 -0.4 0.25 0 -0 0</pose>
        <parent>base_link</parent>
        <child>right_steering_link</child>
        <axis>
          <xyz>0 0 -1</xyz>
          <limit>
            <lower>0</lower>
            <upper>0</upper>
            <effort>1e+06</effort>
            <velocity>1e+06</velocity>
          </limit>
          <dynamics>
            <spring_reference>0</spring_reference>
            <spring_stiffness>0</spring_stiffness>
          </dynamics>
        </axis>
      </joint>
      <link name='right_steering_link'>
        <pose relative_to='right_front_shock'>0 0 0 0 -0 0</pose>
        <inertial>
          <pose>0 0 0 0 -0 0</pose>
          <mass>0.001</mass>
          <inertia>
            <ixx>0.001</ixx>
            <ixy>0</ixy>
            <ixz>0</ixz>
            <iyy>0.001</iyy>
            <iyz>0</iyz>
            <izz>0.001</izz>
          </inertia>
        </inertial>
        <self_collide>0</self_collide>
        <enable_wind>0</enable_wind>
        <kinematic>0</kinematic>
      </link>
      <joint name='right_steering_joint' type='revolute'>
        <pose relative_to='right_steering_link'>0 0 0 0 -0 0</pose>
        <parent>right_steering_link</parent>
        <child>right_front_axle_carrier</child>
        <axis>
          <xyz>0 0 1</xyz>
          <limit>
            <lower>-0.785398</lower>
            <upper>0.785398</upper>
            <effort>5649</effort>
            <velocity>0.5</velocity>
          </limit>
          <dynamics>
            <damping>0.4</damping>
            <friction>0</friction>
            <spring_reference>0</spring_reference>
            <spring_stiffness>0</spring_stiffness>
          </dynamics>
        </axis>
      </joint>
      <link name='right_front_axle_carrier'>
        <pose relative_to='right_steering_joint'>0 0 0 0 -0 0</pose>
        <inertial>
          <pose>0 0 0 0 -0 0</pose>
          <mass>0.001</mass>
          <inertia>
            <ixx>0.001</ixx>
            <ixy>0</ixy>
            <ixz>0</ixz>
            <iyy>0.001</iyy>
            <iyz>0</iyz>
            <izz>0.001</izz>
          </inertia>
        </inertial>
        <self_collide>0</self_collide>
        <enable_wind>0</enable_wind>
        <kinematic>0</kinematic>
      </link>
      <joint name='right_front_axle' type='revolute'>
        <pose relative_to='right_front_axle_carrier'>0 0 0 1.5708 -0 0</pose>
        <parent>right_front_axle_carrier</parent>
        <child>right_front_wheel</child>
        <axis>
          <xyz>0 0 -1</xyz>
          <limit>
            <lower>-1e+16</lower>
            <upper>1e+16</upper>
          </limit>
          <dynamics>
            <spring_reference>0</spring_reference>
            <spring_stiffness>0</spring_stiffness>
          </dynamics>
        </axis>
      </joint>
      <link name='right_front_wheel'>
        <pose relative_to='right_front_axle'>0 0 0 0 -0 0</pose>
        <inertial>
          <pose>0 0 0 0 -0 0</pose>
          <mass>0.29</mass>
          <inertia>
            <ixx>0.005075</ixx>
            <ixy>0</ixy>
            <ixz>0</ixz>
            <iyy>0.005075</iyy>
            <iyz>0</iyz>
            <izz>0.0090625</izz>
          </inertia>
        </inertial>
        <collision name='right_front_wheel_collision'>
          <pose>0 0 0 0 -0 0</pose>
          <geometry>
            <cylinder>
              <length>0.15</length>
              <radius>0.25</radius>
            </cylinder>
          </geometry>
          <surface>
            <contact>
              <ode>
                <kp>1e+06</kp>
                <kd>1</kd>
              </ode>
            </contact>
            <friction>
              <ode>
                <mu>1</mu>
                <mu2>1</mu2>
              </ode>
              <torsional>
                <ode/>
              </torsional>
            </friction>
            <bounce/>
          </surface>
          <max_contacts>10</max_contacts>
        </collision>
        <visual name='right_front_wheel_visual'>
          <pose>0 0 0 -1.5708 0 0</pose>
          <geometry>
            <mesh>
              <scale>1 1 1</scale>
              <uri>/home/ducthang/agribot/src/tractor/tractor_description/meshes/kubo_front_tire1.dae</uri>
            </mesh>
          </geometry>
        </visual>
        <gravity>1</gravity>
        <velocity_decay/>
        <self_collide>0</self_collide>
        <enable_wind>0</enable_wind>
        <kinematic>0</kinematic>
      </link>
      <joint name='right_rear_shock' type='prismatic'>
        <pose relative_to='base_link'>0 -0.4 0.35 0 -0 0</pose>
        <parent>base_link</parent>
        <child>right_rear_axle_carrier</child>
        <axis>
          <xyz>0 0 -1</xyz>
          <limit>
            <lower>0</lower>
            <upper>0</upper>
            <effort>1e+06</effort>
            <velocity>1e+06</velocity>
          </limit>
          <dynamics>
            <spring_reference>0</spring_reference>
            <spring_stiffness>0</spring_stiffness>
          </dynamics>
        </axis>
      </joint>
      <link name='right_rear_axle_carrier'>
        <pose relative_to='right_rear_shock'>0 0 0 0 -0 0</pose>
        <inertial>
          <pose>0 0 0 0 -0 0</pose>
          <mass>0.001</mass>
          <inertia>
            <ixx>0.001</ixx>
            <ixy>0</ixy>
            <ixz>0</ixz>
            <iyy>0.001</iyy>
            <iyz>0</iyz>
            <izz>0.001</izz>
          </inertia>
        </inertial>
        <self_collide>0</self_collide>
        <enable_wind>0</enable_wind>
        <kinematic>0</kinematic>
      </link>
      <joint name='right_rear_axle' type='revolute'>
        <pose relative_to='right_rear_axle_carrier'>0 0 0 1.5708 -0 0</pose>
        <parent>right_rear_axle_carrier</parent>
        <child>right_rear_wheel</child>
        <axis>
          <xyz>0 0 -1</xyz>
          <limit>
            <lower>-1e+16</lower>
            <upper>1e+16</upper>
          </limit>
          <dynamics>
            <spring_reference>0</spring_reference>
            <spring_stiffness>0</spring_stiffness>
          </dynamics>
        </axis>
      </joint>
      <link name='right_rear_wheel'>
        <pose relative_to='right_rear_axle'>0 0 0 0 -0 0</pose>
        <inertial>
          <pose>0 0 0 0 -0 0</pose>
          <mass>0.29</mass>
          <inertia>
            <ixx>0.00984792</ixx>
            <ixy>0</ixy>
            <ixz>0</ixz>
            <iyy>0.00984792</iyy>
            <iyz>0</iyz>
            <izz>0.0177625</izz>
          </inertia>
        </inertial>
        <collision name='right_rear_wheel_collision'>
          <pose>0 0 0 0 -0 0</pose>
          <geometry>
            <cylinder>
              <length>0.2</length>
              <radius>0.35</radius>
            </cylinder>
          </geometry>
          <surface>
            <contact>
              <ode>
                <kp>1e+06</kp>
                <kd>1</kd>
              </ode>
            </contact>
            <friction>
              <ode>
                <mu>1</mu>
                <mu2>1</mu2>
                <fdir1>1 0 0</fdir1>
              </ode>
              <torsional>
                <ode/>
              </torsional>
            </friction>
            <bounce/>
          </surface>
          <max_contacts>10</max_contacts>
        </collision>
        <visual name='right_rear_wheel_visual'>
          <pose>0 0 0 -1.5708 0 0</pose>
          <geometry>
            <mesh>
              <scale>1 1 1</scale>
              <uri>/home/ducthang/agribot/src/tractor/tractor_description/meshes/kubo_back_tire1.dae</uri>
            </mesh>
          </geometry>
        </visual>
        <gravity>1</gravity>
        <velocity_decay/>
        <self_collide>0</self_collide>
        <enable_wind>0</enable_wind>
        <kinematic>0</kinematic>
      </link>
      <plugin name='gazebo_ros_control' filename='libgazebo_ros_control.so'>
        <robotNamespace/>
        <robotParam>/robot_description</robotParam>
        <controlPeriod>0.001</controlPeriod>
        <legacyModeNS>1</legacyModeNS>
        <robotSimType>gazebo_ros_control/DefaultRobotHWSim</robotSimType>
      </plugin>
      <plugin name='differential_drive_controller_front' filename='libgazebo_ros_diff_drive.so'>
        <rosDebugLevel>Debug</rosDebugLevel>
        <publishWheelTF>1</publishWheelTF>
        <publishTf>1</publishTf>
        <publishWheelJointState>1</publishWheelJointState>
        <alwaysOn>1</alwaysOn>
        <updateRate>100.0</updateRate>
        <leftJoint>left_rear_axle</leftJoint>
        <rightJoint>right_rear_axle</rightJoint>
        <wheelSeparation>0.8</wheelSeparation>
        <wheelDiameter>0.7</wheelDiameter>
        <broadcastTF>1</broadcastTF>
        <wheelTorque>30</wheelTorque>
        <wheelAcceleration>1.8</wheelAcceleration>
        <commandTopic>cmd_vel</commandTopic>
        <odometryFrame>odom</odometryFrame>
        <odometryTopic>odom</odometryTopic>
        <robotBaseFrame>base_link</robotBaseFrame>
        <robotNamespace>/</robotNamespace>
      </plugin>
      <plugin name='gazebo_ros_gps' filename='libhector_gazebo_ros_gps.so'>
        <updateRate>4.0</updateRate>
        <frameId>base_link</frameId>
        <topicName>/gps/fix</topicName>
        <velocityTopicName>/gps/fix_velocity</velocityTopicName>
        <referenceLatitude>42</referenceLatitude>
        <referenceLongitude>-71</referenceLongitude>
        <referenceHeading>90</referenceHeading>
        <referenceAltitude>0</referenceAltitude>
        <offset>0 0 0</offset>
        <drift>0.001 0.001 0.001</drift>
        <gaussianNoise>0.1 0.1 0.1</gaussianNoise>
        <velocityDrift>0.001 0.001 0.001</velocityDrift>
        <velocityGaussianNoise>0.5 0.5 0.5</velocityGaussianNoise>
        <robotNamespace>/</robotNamespace>
        <bodyName>base_link</bodyName>
        <xyzOffset>0 0 -2</xyzOffset>
        <rpyOffset>0 -0 0</rpyOffset>
      </plugin>
      <plugin name='imu_plugin' filename='libhector_gazebo_ros_imu.so'>
        <updateRate>10.0</updateRate>
        <topicName>imu/data_raw</topicName>
        <serviceName>imu_service</serviceName>
        <frame_id>odom</frame_id>
        <alwaysOn>1</alwaysOn>
        <accelOffset>0.0 0.0 0.0</accelOffset>
        <accelDrift>0.0 0.0 0.0</accelDrift>
        <accelDriftFrequency>0.00027 0.00027 0.000027</accelDriftFrequency>
        <accelGaussianNoise>0.0 0.0 0.0</accelGaussianNoise>
        <rateOffset>0.0 0.0 0.0</rateOffset>
        <rateDrift>0.0 0.0 0.0</rateDrift>
        <rateDriftFrequency>0.00027 0.00027 0.000027</rateDriftFrequency>
        <rateGaussianNoise>0.0 0.0 0.0</rateGaussianNoise>
        <yawOffset>0.0</yawOffset>
        <yawDrift>0.0</yawDrift>
        <yawDriftFrequency>0.00027</yawDriftFrequency>
        <yawGaussianNoise>0.0</yawGaussianNoise>
        <robotNamespace>/</robotNamespace>
        <bodyName>base_link</bodyName>
        <xyzOffset>0.3 0 -1</xyzOffset>
        <rpyOffset>0 -0 0</rpyOffset>
      </plugin>
      <static>0</static>
      <plugin name='hitch_control' filename='libhitch_plugin.so'>
        <robotNamespace>/</robotNamespace>
      </plugin>
      <pose>0 0 0 0 -0 0</pose>
    </model>
    <model name='unit_box'>
      <pose>7.923 -5.56973 0.5 0 -0 0</pose>
      <link name='link'>
        <inertial>
          <mass>1</mass>
          <inertia>
            <ixx>0.166667</ixx>
            <ixy>0</ixy>
            <ixz>0</ixz>
            <iyy>0.166667</iyy>
            <iyz>0</iyz>
            <izz>0.166667</izz>
          </inertia>
          <pose>0 0 0 0 -0 0</pose>
        </inertial>
        <collision name='collision'>
          <geometry>
            <box>
              <size>1 0.143057 12.2534</size>
            </box>
          </geometry>
          <max_contacts>10</max_contacts>
          <surface>
            <contact>
              <ode/>
            </contact>
            <bounce/>
            <friction>
              <torsional>
                <ode/>
              </torsional>
              <ode/>
            </friction>
          </surface>
        </collision>
        <visual name='visual'>
          <geometry>
            <box>
              <size>1 0.143057 12.2534</size>
            </box>
          </geometry>
          <material>
            <script>
              <name>Gazebo/Grey</name>
              <uri>file://media/materials/scripts/gazebo.material</uri>
            </script>
          </material>
        </visual>
        <self_collide>0</self_collide>
        <enable_wind>0</enable_wind>
        <kinematic>0</kinematic>
      </link>
    </model>
    <model name='unit_box_clone'>
      <pose>14.1399 3.1812 0.034332 0 -0 0</pose>
      <link name='link'>
        <inertial>
          <mass>1</mass>
          <inertia>
            <ixx>0.166667</ixx>
            <ixy>0</ixy>
            <ixz>0</ixz>
            <iyy>0.166667</iyy>
            <iyz>0</iyz>
            <izz>0.166667</izz>
          </inertia>
          <pose>0 0 0 0 -0 0</pose>
        </inertial>
        <collision name='collision'>
          <geometry>
            <box>
              <size>1 6.99023 0.039045</size>
            </box>
          </geometry>
          <max_contacts>10</max_contacts>
          <surface>
            <contact>
              <ode/>
            </contact>
            <bounce/>
            <friction>
              <torsional>
                <ode/>
              </torsional>
              <ode/>
            </friction>
          </surface>
        </collision>
        <visual name='visual'>
          <geometry>
            <box>
              <size>1 6.99023 0.039045</size>
            </box>
          </geometry>
          <material>
            <script>
              <name>Gazebo/Grey</name>
              <uri>file://media/materials/scripts/gazebo.material</uri>
            </script>
          </material>
        </visual>
        <self_collide>0</self_collide>
        <enable_wind>0</enable_wind>
        <kinematic>0</kinematic>
      </link>
    </model>
    <model name='unit_box_clone_0'>
      <pose>24.495 -5.25888 0.034327 0 -1e-05 0</pose>
      <link name='link'>
        <inertial>
          <mass>1</mass>
          <inertia>
            <ixx>0.166667</ixx>
            <ixy>0</ixy>
            <ixz>0</ixz>
            <iyy>0.166667</iyy>
            <iyz>0</iyz>
            <izz>0.166667</izz>
          </inertia>
          <pose>0 0 0 0 -0 0</pose>
        </inertial>
        <collision name='collision'>
          <geometry>
            <box>
              <size>1 6.99023 0.068663</size>
            </box>
          </geometry>
          <max_contacts>10</max_contacts>
          <surface>
            <contact>
              <ode/>
            </contact>
            <bounce/>
            <friction>
              <torsional>
                <ode/>
              </torsional>
              <ode/>
            </friction>
          </surface>
        </collision>
        <visual name='visual'>
          <geometry>
            <box>
              <size>1 6.99023 0.068663</size>
            </box>
          </geometry>
          <material>
            <script>
              <name>Gazebo/Grey</name>
              <uri>file://media/materials/scripts/gazebo.material</uri>
            </script>
          </material>
        </visual>
        <self_collide>0</self_collide>
        <enable_wind>0</enable_wind>
        <kinematic>0</kinematic>
      </link>
    </model>
    <model name='unit_box_clone_1'>
      <pose>34.94 3.54887 0.034327 0 -1e-05 0</pose>
      <link name='link'>
        <inertial>
          <mass>1</mass>
          <inertia>
            <ixx>0.166667</ixx>
            <ixy>0</ixy>
            <ixz>0</ixz>
            <iyy>0.166667</iyy>
            <iyz>0</iyz>
            <izz>0.166667</izz>
          </inertia>
          <pose>0 0 0 0 -0 0</pose>
        </inertial>
        <collision name='collision'>
          <geometry>
            <box>
              <size>1 6.99023 0.068663</size>
            </box>
          </geometry>
          <max_contacts>10</max_contacts>
          <surface>
            <contact>
              <ode/>
            </contact>
            <bounce/>
            <friction>
              <torsional>
                <ode/>
              </torsional>
              <ode/>
            </friction>
          </surface>
        </collision>
        <visual name='visual'>
          <geometry>
            <box>
              <size>1 6.99023 0.068663</size>
            </box>
          </geometry>
          <material>
            <script>
              <name>Gazebo/Grey</name>
              <uri>file://media/materials/scripts/gazebo.material</uri>
            </script>
          </material>
        </visual>
        <self_collide>0</self_collide>
        <enable_wind>0</enable_wind>
        <kinematic>0</kinematic>
      </link>
    </model>
    <model name='unit_box_clone_2'>
      <pose>14.0371 -5.54187 0.040805 0 -0 0.02115</pose>
      <link name='link'>
        <inertial>
          <mass>1</mass>
          <inertia>
            <ixx>0.166667</ixx>
            <ixy>0</ixy>
            <ixz>0</ixz>
            <iyy>0.166667</iyy>
            <iyz>0</iyz>
            <izz>0.166667</izz>
          </inertia>
          <pose>0 0 0 0 -0 0</pose>
        </inertial>
        <collision name='collision'>
          <geometry>
            <box>
              <size>1 6.99023 0.08161</size>
            </box>
          </geometry>
          <max_contacts>10</max_contacts>
          <surface>
            <contact>
              <ode/>
            </contact>
            <bounce/>
            <friction>
              <torsional>
                <ode/>
              </torsional>
              <ode/>
            </friction>
          </surface>
        </collision>
        <visual name='visual'>
          <geometry>
            <box>
              <size>1 6.99023 0.08161</size>
            </box>
          </geometry>
          <material>
            <script>
              <name>Gazebo/Grey</name>
              <uri>file://media/materials/scripts/gazebo.material</uri>
            </script>
          </material>
        </visual>
        <self_collide>0</self_collide>
        <enable_wind>0</enable_wind>
        <kinematic>0</kinematic>
      </link>
    </model>
    <model name='unit_box_clone_3'>
      <pose>20.5599 3.40657 0.040805 0 -0 0.02115</pose>
      <link name='link'>
        <inertial>
          <mass>1</mass>
          <inertia>
            <ixx>0.166667</ixx>
            <ixy>0</ixy>
            <ixz>0</ixz>
            <iyy>0.166667</iyy>
            <iyz>0</iyz>
            <izz>0.166667</izz>
          </inertia>
          <pose>0 0 0 0 -0 0</pose>
        </inertial>
        <collision name='collision'>
          <geometry>
            <box>
              <size>1 6.99023 0.08161</size>
            </box>
          </geometry>
          <max_contacts>10</max_contacts>
          <surface>
            <contact>
              <ode/>
            </contact>
            <bounce/>
            <friction>
              <torsional>
                <ode/>
              </torsional>
              <ode/>
            </friction>
          </surface>
        </collision>
        <visual name='visual'>
          <geometry>
            <box>
              <size>1 6.99023 0.08161</size>
            </box>
          </geometry>
          <material>
            <script>
              <name>Gazebo/Grey</name>
              <uri>file://media/materials/scripts/gazebo.material</uri>
            </script>
          </material>
        </visual>
        <self_collide>0</self_collide>
        <enable_wind>0</enable_wind>
        <kinematic>0</kinematic>
      </link>
    </model>
    <model name='unit_box_clone_4'>
      <pose>30.2066 -0.582372 0.0408 0 -1e-05 0.021151</pose>
      <link name='link'>
        <inertial>
          <mass>1</mass>
          <inertia>
            <ixx>0.166667</ixx>
            <ixy>0</ixy>
            <ixz>0</ixz>
            <iyy>0.166667</iyy>
            <iyz>0</iyz>
            <izz>0.166667</izz>
          </inertia>
          <pose>0 0 0 0 -0 0</pose>
        </inertial>
        <collision name='collision'>
          <geometry>
            <box>
              <size>1 6.99023 0.08161</size>
            </box>
          </geometry>
          <max_contacts>10</max_contacts>
          <surface>
            <contact>
              <ode/>
            </contact>
            <bounce/>
            <friction>
              <torsional>
                <ode/>
              </torsional>
              <ode/>
            </friction>
          </surface>
        </collision>
        <visual name='visual'>
          <geometry>
            <box>
              <size>1 6.99023 0.08161</size>
            </box>
          </geometry>
          <material>
            <script>
              <name>Gazebo/Grey</name>
              <uri>file://media/materials/scripts/gazebo.material</uri>
            </script>
          </material>
        </visual>
        <self_collide>0</self_collide>
        <enable_wind>0</enable_wind>
        <kinematic>0</kinematic>
      </link>
    </model>
    <model name='unit_box_clone_5'>
      <pose>40.4995 3.03293 0.040805 0 -0 0.021151</pose>
      <link name='link'>
        <inertial>
          <mass>1</mass>
          <inertia>
            <ixx>0.166667</ixx>
            <ixy>0</ixy>
            <ixz>0</ixz>
            <iyy>0.166667</iyy>
            <iyz>0</iyz>
            <izz>0.166667</izz>
          </inertia>
          <pose>0 0 0 0 -0 0</pose>
        </inertial>
        <collision name='collision'>
          <geometry>
            <box>
              <size>1 6.99023 0.08161</size>
            </box>
          </geometry>
          <max_contacts>10</max_contacts>
          <surface>
            <contact>
              <ode/>
            </contact>
            <bounce/>
            <friction>
              <torsional>
                <ode/>
              </torsional>
              <ode/>
            </friction>
          </surface>
        </collision>
        <visual name='visual'>
          <geometry>
            <box>
              <size>1 6.99023 0.08161</size>
            </box>
          </geometry>
          <material>
            <script>
              <name>Gazebo/Grey</name>
              <uri>file://media/materials/scripts/gazebo.material</uri>
            </script>
          </material>
        </visual>
        <self_collide>0</self_collide>
        <enable_wind>0</enable_wind>
        <kinematic>0</kinematic>
      </link>
    </model>
    <model name='unit_box_clone_6'>
      <pose>37.2252 -6.4942 0.040798 -0 1.5e-05 0.021151</pose>
      <link name='link'>
        <inertial>
          <mass>1</mass>
          <inertia>
            <ixx>0.166667</ixx>
            <ixy>0</ixy>
            <ixz>0</ixz>
            <iyy>0.166667</iyy>
            <iyz>0</iyz>
            <izz>0.166667</izz>
          </inertia>
          <pose>0 0 0 0 -0 0</pose>
        </inertial>
        <collision name='collision'>
          <geometry>
            <box>
              <size>1 6.99023 0.08161</size>
            </box>
          </geometry>
          <max_contacts>10</max_contacts>
          <surface>
            <contact>
              <ode/>
            </contact>
            <bounce/>
            <friction>
              <torsional>
                <ode/>
              </torsional>
              <ode/>
            </friction>
          </surface>
        </collision>
        <visual name='visual'>
          <geometry>
            <box>
              <size>1 6.99023 0.08161</size>
            </box>
          </geometry>
          <material>
            <script>
              <name>Gazebo/Grey</name>
              <uri>file://media/materials/scripts/gazebo.material</uri>
            </script>
          </material>
        </visual>
        <self_collide>0</self_collide>
        <enable_wind>0</enable_wind>
        <kinematic>0</kinematic>
      </link>
    </model>
    <model name='unit_box_clone_7'>
      <pose>44.4088 -4.6774 0.040805 0 -0 0.021151</pose>
      <link name='link'>
        <inertial>
          <mass>1</mass>
          <inertia>
            <ixx>0.166667</ixx>
            <ixy>0</ixy>
            <ixz>0</ixz>
            <iyy>0.166667</iyy>
            <iyz>0</iyz>
            <izz>0.166667</izz>
          </inertia>
          <pose>0 0 0 0 -0 0</pose>
        </inertial>
        <collision name='collision'>
          <geometry>
            <box>
              <size>1 6.99023 0.08161</size>
            </box>
          </geometry>
          <max_contacts>10</max_contacts>
          <surface>
            <contact>
              <ode/>
            </contact>
            <bounce/>
            <friction>
              <torsional>
                <ode/>
              </torsional>
              <ode/>
            </friction>
          </surface>
        </collision>
        <visual name='visual'>
          <geometry>
            <box>
              <size>1 6.99023 0.08161</size>
            </box>
          </geometry>
          <material>
            <script>
              <name>Gazebo/Grey</name>
              <uri>file://media/materials/scripts/gazebo.material</uri>
            </script>
          </material>
        </visual>
        <self_collide>0</self_collide>
        <enable_wind>0</enable_wind>
        <kinematic>0</kinematic>
      </link>
    </model>
    <model name='unit_box_clone_8'>
      <pose>48.508 2.62109 0.040805 0 -0 0.021151</pose>
      <link name='link'>
        <inertial>
          <mass>1</mass>
          <inertia>
            <ixx>0.166667</ixx>
            <ixy>0</ixy>
            <ixz>0</ixz>
            <iyy>0.166667</iyy>
            <iyz>0</iyz>
            <izz>0.166667</izz>
          </inertia>
          <pose>0 0 0 0 -0 0</pose>
        </inertial>
        <collision name='collision'>
          <geometry>
            <box>
              <size>1 6.99023 0.08161</size>
            </box>
          </geometry>
          <max_contacts>10</max_contacts>
          <surface>
            <contact>
              <ode/>
            </contact>
            <bounce/>
            <friction>
              <torsional>
                <ode/>
              </torsional>
              <ode/>
            </friction>
          </surface>
        </collision>
        <visual name='visual'>
          <geometry>
            <box>
              <size>1 6.99023 0.08161</size>
            </box>
          </geometry>
          <material>
            <script>
              <name>Gazebo/Grey</name>
              <uri>file://media/materials/scripts/gazebo.material</uri>
            </script>
          </material>
        </visual>
        <self_collide>0</self_collide>
        <enable_wind>0</enable_wind>
        <kinematic>0</kinematic>
      </link>
    </model>
    <model name='unit_box_clone_9'>
      <pose>56.6978 -5.15043 0.040798 -0 1.5e-05 0.021151</pose>
      <link name='link'>
        <inertial>
          <mass>1</mass>
          <inertia>
            <ixx>0.166667</ixx>
            <ixy>0</ixy>
            <ixz>0</ixz>
            <iyy>0.166667</iyy>
            <iyz>0</iyz>
            <izz>0.166667</izz>
          </inertia>
          <pose>0 0 0 0 -0 0</pose>
        </inertial>
        <collision name='collision'>
          <geometry>
            <box>
              <size>1 6.99023 0.08161</size>
            </box>
          </geometry>
          <max_contacts>10</max_contacts>
          <surface>
            <contact>
              <ode/>
            </contact>
            <bounce/>
            <friction>
              <torsional>
                <ode/>
              </torsional>
              <ode/>
            </friction>
          </surface>
        </collision>
        <visual name='visual'>
          <geometry>
            <box>
              <size>1 6.99023 0.08161</size>
            </box>
          </geometry>
          <material>
            <script>
              <name>Gazebo/Grey</name>
              <uri>file://media/materials/scripts/gazebo.material</uri>
            </script>
          </material>
        </visual>
        <self_collide>0</self_collide>
        <enable_wind>0</enable_wind>
        <kinematic>0</kinematic>
      </link>
    </model>
    <model name='unit_box_clone_10'>
      <pose>64.8387 2.56008 0.0408 0 -1e-05 0.021151</pose>
      <link name='link'>
        <inertial>
          <mass>1</mass>
          <inertia>
            <ixx>0.166667</ixx>
            <ixy>0</ixy>
            <ixz>0</ixz>
            <iyy>0.166667</iyy>
            <iyz>0</iyz>
            <izz>0.166667</izz>
          </inertia>
          <pose>0 0 0 0 -0 0</pose>
        </inertial>
        <collision name='collision'>
          <geometry>
            <box>
              <size>1 6.99023 0.08161</size>
            </box>
          </geometry>
          <max_contacts>10</max_contacts>
          <surface>
            <contact>
              <ode/>
            </contact>
            <bounce/>
            <friction>
              <torsional>
                <ode/>
              </torsional>
              <ode/>
            </friction>
          </surface>
        </collision>
        <visual name='visual'>
          <geometry>
            <box>
              <size>1 6.99023 0.08161</size>
            </box>
          </geometry>
          <material>
            <script>
              <name>Gazebo/Grey</name>
              <uri>file://media/materials/scripts/gazebo.material</uri>
            </script>
          </material>
        </visual>
        <self_collide>0</self_collide>
        <enable_wind>0</enable_wind>
        <kinematic>0</kinematic>
      </link>
    </model>
    <state world_name='my_world'>
      <sim_time>2452 178000000</sim_time>
      <real_time>2545 936851666</real_time>
      <wall_time>1623989128 727679834</wall_time>
      <iterations>2452178</iterations>
      <model name='ground 1'>
        <pose>10 10 0 0 -0 0</pose>
        <scale>1 1 1</scale>
        <link name='link'>
          <pose>10 10 0 0 -0 0</pose>
          <velocity>0 0 0 0 -0 0</velocity>
          <acceleration>0 0 0 0 -0 0</acceleration>
          <wrench>0 0 0 0 -0 0</wrench>
        </link>
      </model>
      <model name='ground 10'>
        <pose>70 -10 0 0 -0 0</pose>
        <scale>1 1 1</scale>
        <link name='link'>
          <pose>70 -10 0 0 -0 0</pose>
          <velocity>0 0 0 0 -0 0</velocity>
          <acceleration>0 0 0 0 -0 0</acceleration>
          <wrench>0 0 0 0 -0 0</wrench>
        </link>
      </model>
      <model name='ground 2'>
        <pose>10 -10 0 0 -0 0</pose>
        <scale>1 1 1</scale>
        <link name='link'>
          <pose>10 -10 0 0 -0 0</pose>
          <velocity>0 0 0 0 -0 0</velocity>
          <acceleration>0 0 0 0 -0 0</acceleration>
          <wrench>0 0 0 0 -0 0</wrench>
        </link>
      </model>
      <model name='ground 3'>
        <pose>-10 10 0 0 -0 0</pose>
        <scale>1 1 1</scale>
        <link name='link'>
          <pose>-10 10 0 0 -0 0</pose>
          <velocity>0 0 0 0 -0 0</velocity>
          <acceleration>0 0 0 0 -0 0</acceleration>
          <wrench>0 0 0 0 -0 0</wrench>
        </link>
      </model>
      <model name='ground 4'>
        <pose>-10 -10 0 0 -0 0</pose>
        <scale>1 1 1</scale>
        <link name='link'>
          <pose>-10 -10 0 0 -0 0</pose>
          <velocity>0 0 0 0 -0 0</velocity>
          <acceleration>0 0 0 0 -0 0</acceleration>
          <wrench>0 0 0 0 -0 0</wrench>
        </link>
      </model>
      <model name='ground 5'>
        <pose>30 10 0 0 -0 0</pose>
        <scale>1 1 1</scale>
        <link name='link'>
          <pose>30 10 0 0 -0 0</pose>
          <velocity>0 0 0 0 -0 0</velocity>
          <acceleration>0 0 0 0 -0 0</acceleration>
          <wrench>0 0 0 0 -0 0</wrench>
        </link>
      </model>
      <model name='ground 6'>
        <pose>30 -10 0 0 -0 0</pose>
        <scale>1 1 1</scale>
        <link name='link'>
          <pose>30 -10 0 0 -0 0</pose>
          <velocity>0 0 0 0 -0 0</velocity>
          <acceleration>0 0 0 0 -0 0</acceleration>
          <wrench>0 0 0 0 -0 0</wrench>
        </link>
      </model>
      <model name='ground 7'>
        <pose>50 10 0 0 -0 0</pose>
        <scale>1 1 1</scale>
        <link name='link'>
          <pose>50 10 0 0 -0 0</pose>
          <velocity>0 0 0 0 -0 0</velocity>
          <acceleration>0 0 0 0 -0 0</acceleration>
          <wrench>0 0 0 0 -0 0</wrench>
        </link>
      </model>
      <model name='ground 8'>
        <pose>50 -10 0 0 -0 0</pose>
        <scale>1 1 1</scale>
        <link name='link'>
          <pose>50 -10 0 0 -0 0</pose>
          <velocity>0 0 0 0 -0 0</velocity>
          <acceleration>0 0 0 0 -0 0</acceleration>
          <wrench>0 0 0 0 -0 0</wrench>
        </link>
      </model>
      <model name='ground 9'>
        <pose>70 10 0 0 -0 0</pose>
        <scale>1 1 1</scale>
        <link name='link'>
          <pose>70 10 0 0 -0 0</pose>
          <velocity>0 0 0 0 -0 0</velocity>
          <acceleration>0 0 0 0 -0 0</acceleration>
          <wrench>0 0 0 0 -0 0</wrench>
        </link>
      </model>
      <model name='lawn_tractor'>
        <pose>69.8102 0.149001 -0.000374 -1.4e-05 -0.000297 -0.69119</pose>
        <scale>1 1 1</scale>
        <link name='base_link'>
          <pose>69.8102 0.149001 -0.000374 -1.4e-05 -0.000297 -0.69119</pose>
          <velocity>7.4e-05 -6.1e-05 2e-06 2e-06 -0 5e-06</velocity>
          <acceleration>-0.000528 0.000549 -1.1e-05 3.5e-05 -0.000231 0.000429</acceleration>
          <wrench>-0.001632 0.001696 -3.5e-05 0 -0 0</wrench>
        </link>
        <link name='left_front_axle_carrier'>
          <pose>70.9898 -0.307554 0.25001 3.7e-05 -0.000312 -0.69112</pose>
          <velocity>4.2e-05 -4.2e-05 -2e-06 1.1e-05 -1.1e-05 0.00106</velocity>
          <acceleration>0.005726 -0.005062 -0.002071 -0.003215 0.003693 -0.08668</acceleration>
          <wrench>6e-06 -5e-06 -2e-06 0 -0 0</wrench>
        </link>
        <link name='left_front_wheel'>
          <pose>70.9898 -0.307583 0.250002 1.57085 0.782831 -0.691083</pose>
          <velocity>4.8e-05 -4.4e-05 -2e-06 0.000379 0.000437 0.001061</velocity>
          <acceleration>0.004335 -0.003655 -0.001971 -0.00132 -0.001927 -0.159764</acceleration>
          <wrench>0.001257 -0.00106 -0.000572 0 -0 0</wrench>
        </link>
        <link name='left_rear_axle_carrier'>
          <pose>70.0651 0.457269 0.350161 3.8e-05 -0.000285 -0.691191</pose>
          <velocity>6.5e-05 -6.7e-05 -5e-06 1.5e-05 -1.9e-05 1e-05</velocity>
          <acceleration>-0.003663 0.000149 0.000731 -0.000466 -0.009038 0.002522</acceleration>
          <wrench>-4e-06 0 1e-06 0 -0 0</wrench>
        </link>
        <link name='left_rear_wheel'>
          <pose>70.0651 0.45727 0.350003 1.57085 -0.151847 -0.691199</pose>
          <velocity>6.8e-05 -6.5e-05 -7e-06 0.000186 0.000192 9e-06</velocity>
          <acceleration>-0.002698 0.000294 0.000513 0.001228 -0.005208 0.003856</acceleration>
          <wrench>-0.000782 8.5e-05 0.000149 0 -0 0</wrench>
        </link>
        <link name='left_steering_link'>
          <pose>70.9898 -0.307622 0.249991 1.4e-05 -0.000312 -0.691118</pose>
          <velocity>5.6e-05 -4.7e-05 1e-06 -2e-06 1e-06 5e-06</velocity>
          <acceleration>0.002928 -0.002529 -0.001433 0.000574 0.000515 -0.000415</acceleration>
          <wrench>3e-06 -3e-06 -1e-06 0 -0 0</wrench>
        </link>
        <link name='right_front_axle_carrier'>
          <pose>70.4796 -0.924232 0.250009 -6.3e-05 -0.000307 -0.691255</pose>
          <velocity>3.9e-05 -2.9e-05 -4e-06 -6e-06 4e-06 -0.001198</velocity>
          <acceleration>0.002703 0.008716 -0.003289 0.031164 -0.024315 0.140509</acceleration>
          <wrench>3e-06 9e-06 -3e-06 0 -0 0</wrench>
        </link>
        <link name='right_front_wheel'>
          <pose>70.4796 -0.924204 0.250004 -1.57074 -0.210971 2.45032</pose>
          <velocity>4.6e-05 -3.5e-05 -4e-06 0.000367 0.000461 -0.0012</velocity>
          <acceleration>0.005688 0.001337 -0.004454 -0.020747 0.004138 0.190829</acceleration>
          <wrench>0.001649 0.000388 -0.001292 0 -0 0</wrench>
        </link>
        <link name='right_rear_axle_carrier'>
          <pose>69.5551 -0.159137 0.349463 -0.000137 -0.000283 -0.691192</pose>
          <velocity>7.6e-05 -6.8e-05 2e-06 8e-06 -2e-06 5e-06</velocity>
          <acceleration>-0.000838 0.002206 0.000539 -0.001968 -0.000829 0.000687</acceleration>
          <wrench>-1e-06 2e-06 1e-06 0 -0 0</wrench>
        </link>
        <link name='right_rear_wheel'>
          <pose>69.5551 -0.159136 0.350006 1.57072 -0.333682 -0.691165</pose>
          <velocity>7.6e-05 -5.4e-05 -7e-06 0.00015 0.00021 -4e-06</velocity>
          <acceleration>0.000463 -0.002492 -0.000639 0.005209 -0.000987 0.004845</acceleration>
          <wrench>0.000134 -0.000723 -0.000185 0 -0 0</wrench>
        </link>
        <link name='right_steering_link'>
          <pose>70.4797 -0.924167 0.249996 -4.1e-05 -0.000308 -0.691259</pose>
          <velocity>5.5e-05 -4e-05 -1e-06 3e-06 -4e-06 -1e-06</velocity>
          <acceleration>0.004848 0.00104 -0.002547 -0.009773 0.009281 0.001442</acceleration>
          <wrench>5e-06 1e-06 -3e-06 0 -0 0</wrench>
        </link>
      </model>
      <model name='unit_box'>
        <pose>7.95384 -5.5705 0.040798 0 1.5e-05 0.022588</pose>
        <scale>1 6.99023 0.08161</scale>
        <link name='link'>
          <pose>7.95384 -5.5705 0.040798 0 1.5e-05 0.022588</pose>
          <velocity>0 0 0 0 -0 0</velocity>
          <acceleration>1.42982 0.032379 2.02864 2.34775 -0.56913 -3.14148</acceleration>
          <wrench>1.42982 0.032379 2.02864 0 -0 0</wrench>
        </link>
      </model>
      <model name='unit_box_clone'>
        <pose>14.1421 3.22524 0.060374 0 0 -0.027371</pose>
        <scale>1 1 1.75858</scale>
        <link name='link'>
          <pose>14.1421 3.22524 0.060374 0 0 -0.027371</pose>
          <velocity>0 0 0 0 -0 0</velocity>
          <acceleration>-2.10504 0.057793 7.69054 2.18399 0.394727 -3.14144</acceleration>
          <wrench>-2.10504 0.057793 7.69054 0 -0 0</wrench>
        </link>
      </model>
      <model name='unit_box_clone_0'>
        <pose>24.495 -5.25888 0.034327 0 1e-05 0</pose>
        <scale>1 1 1</scale>
        <link name='link'>
          <pose>24.495 -5.25888 0.034327 0 1e-05 0</pose>
          <velocity>0 0 0 0 -0 0</velocity>
          <acceleration>0 0 -9.8 0 -0 0</acceleration>
          <wrench>0 0 -9.8 0 -0 0</wrench>
        </link>
      </model>
      <model name='unit_box_clone_1'>
        <pose>34.9545 3.55346 0.034327 0 -1e-05 0.040158</pose>
        <scale>1 1 1</scale>
        <link name='link'>
          <pose>34.9545 3.55346 0.034327 0 -1e-05 0.040158</pose>
          <velocity>0 0 0 0 -0 0</velocity>
          <acceleration>0 0 -9.8 0 -0 0</acceleration>
          <wrench>0 0 -9.8 0 -0 0</wrench>
        </link>
      </model>
      <model name='unit_box_clone_10'>
        <pose>64.8612 2.55335 0.040797 0 -1.5e-05 -0.001423</pose>
        <scale>1 1 1</scale>
        <link name='link'>
          <pose>64.8612 2.55335 0.040797 0 -1.5e-05 -0.001423</pose>
          <velocity>0 0 0 0 -0 0</velocity>
          <acceleration>-1.43014 0.002039 2.02865 3.09172 0.578107 -3.14146</acceleration>
          <wrench>-1.43014 0.002039 2.02865 0 -0 0</wrench>
        </link>
      </model>
      <model name='unit_box_clone_2'>
        <pose>14.0614 -5.55231 0.040797 0 1.5e-05 0.019917</pose>
        <scale>1 1 1</scale>
        <link name='link'>
          <pose>14.0614 -5.55231 0.040797 0 1.5e-05 0.019917</pose>
          <velocity>0 0 0 0 -0 0</velocity>
          <acceleration>1.42989 0.02855 2.02864 2.44161 -0.571144 -3.14148</acceleration>
          <wrench>1.42989 0.02855 2.02864 0 -0 0</wrench>
        </link>
      </model>
      <model name='unit_box_clone_3'>
        <pose>20.5745 3.39827 0.0408 0 1e-05 0.030875</pose>
        <scale>1 1 1</scale>
        <link name='link'>
          <pose>20.5745 3.39827 0.0408 0 1e-05 0.030875</pose>
          <velocity>0 0 0 0 -0 0</velocity>
          <acceleration>0 0 -9.8 0 -0 0</acceleration>
          <wrench>0 0 -9.8 0 -0 0</wrench>
        </link>
      </model>
      <model name='unit_box_clone_4'>
        <pose>30.2066 -0.582372 0.0408 0 -1e-05 0.021153</pose>
        <scale>1 1 1</scale>
        <link name='link'>
          <pose>30.2066 -0.582372 0.0408 0 -1e-05 0.021153</pose>
          <velocity>0 0 0 0 -0 0</velocity>
          <acceleration>0 0 -9.8 0 -0 0</acceleration>
          <wrench>0 0 -9.8 0 -0 0</wrench>
        </link>
      </model>
      <model name='unit_box_clone_5'>
        <pose>40.5183 3.04066 0.0408 -0 1e-05 0.010551</pose>
        <scale>1 1 1</scale>
        <link name='link'>
          <pose>40.5183 3.04066 0.0408 -0 1e-05 0.010551</pose>
          <velocity>0 0 0 0 -0 0</velocity>
          <acceleration>0 0 -9.8 0 -0 0</acceleration>
          <wrench>0 0 -9.8 0 -0 0</wrench>
        </link>
      </model>
      <model name='unit_box_clone_6'>
        <pose>37.2252 -6.4942 0.0408 0 1e-05 0.021153</pose>
        <scale>1 1 1</scale>
        <link name='link'>
          <pose>37.2252 -6.4942 0.0408 0 1e-05 0.021153</pose>
          <velocity>0 0 0 0 -0 0</velocity>
          <acceleration>0 0 -9.8 0 -0 0</acceleration>
          <wrench>0 0 -9.8 0 -0 0</wrench>
        </link>
      </model>
      <model name='unit_box_clone_7'>
        <pose>44.354 -1.54117 0.040805 0 -0 -0.038417</pose>
        <scale>1 1 1</scale>
        <link name='link'>
          <pose>44.354 -1.54117 0.040805 0 -0 -0.038417</pose>
          <velocity>0 0 0 0 -0 0</velocity>
          <acceleration>1.42918 -0.055064 7.77139 -1.79173 -0.552068 -3.14149</acceleration>
          <wrench>1.42918 -0.055064 7.77139 0 -0 0</wrench>
        </link>
      </model>
      <model name='unit_box_clone_8'>
        <pose>48.508 2.62109 0.0408 0 -1e-05 0.021152</pose>
        <scale>1 1 1</scale>
        <link name='link'>
          <pose>48.508 2.62109 0.0408 0 -1e-05 0.021152</pose>
          <velocity>0 0 0 0 -0 0</velocity>
          <acceleration>0 0 -9.8 -0 -0 -0</acceleration>
          <wrench>0 0 -9.8 0 -0 0</wrench>
        </link>
      </model>
      <model name='unit_box_clone_9'>
        <pose>56.6978 -5.15043 0.0408 0 1e-05 0.021152</pose>
        <scale>1 1 1</scale>
        <link name='link'>
          <pose>56.6978 -5.15043 0.0408 0 1e-05 0.021152</pose>
          <velocity>0 0 0 0 -0 0</velocity>
          <acceleration>0 0 -9.8 0 -0 0</acceleration>
          <wrench>0 0 -9.8 0 -0 0</wrench>
        </link>
      </model>
      <light name='sun'>
        <pose>0 0 10 0 -0 0</pose>
      </light>
    </state>
    <gui fullscreen='0'>
      <camera name='user_camera'>
        <pose>51.0565 -58.2829 30.5987 0 0.587643 1.79619</pose>
        <view_controller>orbit</view_controller>
        <projection_type>perspective</projection_type>
      </camera>
    </gui>
  </world>
</sdf>
